Workbook

Sheet 00_СТАРТ
A1: РОБОЧА МОДЕЛЬ СЦЕНАРІЇВ ТРАНСПОРТНОЇ МЕРЕЖІ
A3: Крок | B3: Дія | C3: Вкладка | D3: Що робити
A4: 1 | B4: Налаштуй припущення | C4: 01_Параметри | D4: Змінюй лише жовту клітинку B14: середня кількість ТТ у маршруті.
A5: 2 | B5: Створи сценарій | C5: 07A_Конструктор | D5: У колонці D встанови Так або Ні для кожного переходу.
A6: 3 | B6: Подивись підсумок | C6: 10_Дашборд | D6: Контроль пробігу, кількості маршрутів, змінених потоків та лімітів РЦ.
A7: 4 | B7: Розбери деталі | C7: Результат сценарію | D7: Фільтруй статус ЗМІНЕНО або НЕМАЄ МАРШРУТУ.
A8: 5 | B8: Поверни базу | C8: 07A_Конструктор | D8: Встанови Так для всіх 13 переходів.
A10: Важливо | B10: Абсолютний пробіг є оцінкою. Модель порівнює сценарії мостів і не оптимізує фактичну послідовність відвідування ТТ усередині маршруту.

Sheet 01_Параметри
A1: ПАРАМЕТРИ ПОВНОЇ МОДЕЛІ МЕРЕЖІ
A2: Параметр | B2: Значення | C2: Одиниця | D2: Використання | F2: Тип авто | G2: Місткість, палет | H2: Правило вибору
A3: Горизонт моделювання | B3: 30 | C3: днів | D3: Розрахунок загального попиту | F3: 5 т | G3: 14 | H3: залишок до 14 палет
A4: Потужність РЦЧ | B4: 200 | C4: палет/день | D4: Період джерела: вересень 2026 | F4: 7 т | G4: 16 | H4: залишок 15–16 палет
A5: Попит РЦЧ на 1 ТТ | B5: 1 | C5: палета/день | D5: Тимчасове значення до фактичних даних | F5: 10 т | G5: 20 | H5: залишок 17–20 палет
A6: Коефіцієнт дорожньої відстані | B6: 1.2 | C6: коефіцієнт | D6: Фактичний список ТТ з файлу РЦЧ (пикинг).xlsx
A7: Максимальна місткість авто | B7: 20 | C7: палет | D7: Верхня місткість парку; деталізація 5/7/10 т у таблиці праворуч | F7: ЛІМІТИ РЦ
A8: Вартість 1 км | C8: грн/км | D8: Ввід користувача | F8: РЦ | G8: Максимум ТТ
A9: Вартість 1 палети | C9: грн/палета | D9: Ввід користувача | F9: РЦП | G9: 800
A10: Активний сценарій | B10: S0 | C10: код | D10: Перемикач сценарію | F10: РЦВ | G10: 500
A11: Кількість резервних маршрутів | B11: 2 | C11: маршрути | D11: Основний плюс два резервні | F11: РЦЛ | G11: 700
A12: Допустимий приріст кілометражу | C12: % | D12: Ввід користувача | F12: РЦК | G12: 200
A13: Допустимий приріст часу | C13: % | D13: Ввід користувача | F13: РЦЧ | G13: 200
A14: Середня кількість ТТ у маршруті | B14: 4 | C14: ТТ/маршрут | D14: Користувацьке припущення; змінює оцінний пробіг і кількість маршрутів
A15: ДЖЕРЕЛА ДАНИХ
A16: Все ТТ.xlsx | B16: ТТ, координати, чинний РЦ, палети; агрегати РЦ | C16: Вересень 2026 | D16: Реальні дані
A17: РЦЧ (пикинг).xlsx | B17: Ознака паралельного потоку РЦЧ | D17: Реальні дані
A18: РЦК макси.xlsx | B18: 347 ТТ, координати та чинні депо | D18: Реальні дані
A19: Правило потоку РЦК макси | B19: Паралельний потік на ті самі ТТ; обсяг по ТТ відсутній у джерелі | D19: Обсяг не моделюється
A20: КОНТРОЛЬНА ЛОГІКА МЕРЕЖІ
A21: Базові унікальні ТТ | B21: 1929 | C21: ТТ | D21: 715 РЦП + 600 РЦВ + 614 РЦЛ
A22: РЦК макси | B22: 347 | C22: потоків | D22: Це ті самі ТТ, не нові унікальні ТТ
A23: РЦЧ | B23: 168 | C23: потоків | D23: Окремий паралельний SKU-потік
A24: Сума рядків джерел | B24: 2276 | C24: рядків | D24: 1929 + 347
A25: Усього потоків | B25: 2444 | C25: потоків | D25: 1929 + 347 + 168
A26: Палети | D26: Розподілені як середні по РЦ з агрегатів Все ТТ.xlsx
A28: МЕТОД РОЗРАХУНКУ МАРШРУТІВ
A29: Метод оцінного пробігу | B29: Сума еквівалентного пробігу ÷ середня кількість ТТ у маршруті
A30: Ліміти РЦ | B30: Контроль лише базових унікальних ТТ; паралельні SKU-потоки РЦК/РЦЧ не дублюють ТТ у ліміті
A31: Прямий маршрут | B31: Дозволений, якщо РЦ і ТТ визначені на одній стороні Дніпра
A32: Пробіг | B32: 2 × відстань × палет/день ÷ місткість авто
A33: Обмеження | B33: Це планова координатна модель, не дорожній роутер; значення придатні для порівняння сценаріїв

Sheet 07A_Конструктор
A1: КОНСТРУКТОР СЦЕНАРІЮ: БУДЬ-ЯКА КОМБІНАЦІЯ 13 ПЕРЕХОДІВ
A2: Робота користувача: у колонці D виберіть «Так/Ні». Параметр ТТ/маршрут змінюється на 01_Параметри!B14.
A4: Bridge_ID | B4: Вузол | C4: Перехід | D4: Доступний | E4: Закритий | F4: Група | H4: ПІДСУМОК КОНФІГУРАЦІЇ
A5: KYI_DARN | B5: Київ | C5: Дарницький міст | D5: Так | E5: =IF(D5="Ні",1,0) -> 0 | F5: Київ | H5: Показник | I5: Значення
A6: KYI_SOUTH | B6: Київ | C6: Південний міст | D6: Так | E6: =IF(D6="Ні",1,0) -> 0 | F6: Київ | H6: Активні переходи | I6: =COUNTIF(D5:D17,"Так") -> 13
A7: KYI_NORTH | B7: Київ | C7: Північний міст | D7: Так | E7: =IF(D7="Ні",1,0) -> 0 | F7: Київ | H7: Закриті переходи | I7: =COUNTIF(D5:D17,"Ні") -> 0
A8: KYI_HPP | B8: Вишгород | C8: Київська ГЕС | D8: Так | E8: =IF(D8="Ні",1,0) -> 0 | F8: Київ | H8: Рівень ризику | I8: =IF(I7<=2,"Зелений",IF(I7<=5,"Жовтий",IF(I7<=8,"Помаранчевий","Червоний"))) -> Зелений
A9: KANIV_HPP | B9: Канів | C9: Канівська ГЕС | D9: Так | E9: =IF(D9="Ні",1,0) -> 0 | F9: Канів | H9: Базовий оцінний пробіг, км/день | I9: ='Результат сценарію'!B5 -> 241526.75
A10: CHK | B10: Черкаси | C10: Черкаський міст | D10: Так | E10: =IF(D10="Ні",1,0) -> 0 | F10: Черкаси | H10: Пробіг сценарію, км/день | I10: ='Результат сценарію'!B6 -> 241526.75
A11: KREM | B11: Кременчук | C11: Кременчуцький міст | D11: Так | E11: =IF(D11="Ні",1,0) -> 0 | F11: Кременчук | H11: Зміна пробігу, км/день | I11: ='Результат сценарію'!B7 -> 0
A12: KAM_HPP | B12: Кам’янське | C12: Середньодніпровська ГЕС | D12: Так | E12: =IF(D12="Ні",1,0) -> 0 | F12: Дніпро | H12: Зміна пробігу, % | I12: ='Результат сценарію'!B8 -> 0
A13: DNI_AMUR | B13: Дніпро | C13: Амурський міст | D13: Так | E13: =IF(D13="Ні",1,0) -> 0 | F13: Дніпро | H13: Маршрутів/день | I13: ='Результат сценарію'!E5 -> 483
A14: DNI_CENTR | B14: Дніпро | C14: Центральний міст | D14: Так | E14: =IF(D14="Ні",1,0) -> 0 | F14: Дніпро | H14: Потоки зі зміною | I14: ='Результат сценарію'!E6 -> 0
A15: DNI_SOUTH | B15: Дніпро | C15: Південний міст | D15: Так | E15: =IF(D15="Ні",1,0) -> 0 | F15: Дніпро | H15: Недоступні потоки | I15: ='Результат сценарію'!E7 -> 0
A16: ZP_PREOBR | B16: Запоріжжя | C16: Мости Преображенського | D16: Так | E16: =IF(D16="Ні",1,0) -> 0 | F16: Запоріжжя | H16: ТТ/маршрут | I16: ='01_Параметри'!B14 -> 4
A17: ZP_NEW | B17: Запоріжжя | C17: Нові мостові переходи | D17: Так | E17: =IF(D17="Ні",1,0) -> 0 | F17: Запоріжжя | H17: Перепризначено ТТ між РЦ | I17: =COUNTIF('03B_Призначення_РЦ'!D:D,"Так") -> 100

Sheet 10_Дашборд
A1: ДАШБОРД ПОВНОЇ МОДЕЛІ МЕРЕЖІ
A3: KPI | B3: Значення | D3: ПОТОЧНИЙ СЦЕНАРІЙ
A4: Рядків у джерелах | B4: 2276 | D4: Показник | E4: Значення | F4: Ліміт ТТ | G4: Резерв | H4: Статус
A5: Унікальних ТТ | B5: 1929 | D5: ТТ на маршрут | E5: ='01_Параметри'!B14 -> 4 | F5: ='02_РЦ'!E3 -> 800 | G5: РЦ | H5: Базові ТТ | I5: Ліміт | J5: Статус
A6: Основних потоків | B6: 1929 | D6: Маршрутів/день | E6: ='Результат сценарію'!E5 -> 483 | F6: ='02_РЦ'!E4 -> 500 | G6: ='02_РЦ'!A3 -> РЦП | H6: ='02_РЦ'!H3 -> 800 | I6: ='02_РЦ'!E3 -> 800 | J6: ='02_РЦ'!I3 -> В межах
A7: Потоків РЦК макси | B7: 347 | D7: Зміна пробігу, % | E7: ='Результат сценарію'!B8 -> 0 | F7: ='02_РЦ'!E5 -> 700 | G7: ='02_РЦ'!A4 -> РЦВ | H7: ='02_РЦ'!H4 -> 500 | I7: ='02_РЦ'!E4 -> 500 | J7: ='02_РЦ'!I4 -> В межах
A8: Потоків РЦЧ | B8: 168 | D8: Потоки зі зміною | E8: ='Результат сценарію'!E6 -> 0 | F8: ='02_РЦ'!E6 -> 200 | G8: ='02_РЦ'!A5 -> РЦЛ | H8: ='02_РЦ'!H5 -> 614 | I8: ='02_РЦ'!E5 -> 700 | J8: ='02_РЦ'!I5 -> В межах
A9: Усього потоків | B9: 2444 | D9: Недоступні потоки | E9: ='Результат сценарію'!E7 -> 0 | F9: ='02_РЦ'!E7 -> 200 | G9: ='02_РЦ'!A6 -> РЦК | H9: ='02_РЦ'!H6 -> 15 | I9: ='02_РЦ'!E6 -> 200 | J9: ='02_РЦ'!I6 -> В межах
A10: РЦП ТТ | B10: 715 | D10: Перепризначено ТТ між РЦ | E10: ='Результат сценарію'!H7 -> 100 | G10: ='02_РЦ'!A7 -> РЦЧ | H10: ='02_РЦ'!H7 -> 0 | I10: ='02_РЦ'!E7 -> 200 | J10: ='02_РЦ'!I7 -> В межах
A11: РЦВ ТТ | B11: 600
A12: РЦЛ ТТ | B12: 614
A13: Палети: метод | B13: Середнє по РЦ з Все ТТ.xlsx

Sheet Результат сценарію
A1: ="РЕЗУЛЬТАТ СЦЕНАРІЮ: ОЦІНКА ПРИ "&'01_Параметри'!B14&" ТТ/МАРШРУТ" -> РЕЗУЛЬТАТ СЦЕНАРІЮ: ОЦІНКА ПРИ 4 ТТ/МАРШРУТ
A3: ПРИПУЩЕННЯ | B3: Оцінний пробіг агрегує ТТ у маршрути. РЦК/РЦЧ є паралельними SKU-потоками і не дублюють базові ТТ в лімітах РЦ.
A5: Базовий оцінний пробіг, км/день | B5: =SUM(K11:K2453)/'01_Параметри'!$B$14 -> 241526.75 | D5: Оцінна кількість маршрутів/день | E5: =ROUNDUP(COUNTIF('04_Потоки'!$C:$C,"Основний")/'01_Параметри'!$B$14,0) -> 483 | G5: Активні переходи | H5: ='07A_Конструктор'!I6 -> 13
A6: Пробіг сценарію, км/день | B6: =SUM(L11:L2453)/'01_Параметри'!$B$14 -> 241526.75 | D6: Потоки зі зміною | E6: =COUNTIF(G11:G2453,"ЗМІНЕНО") -> 0 | G6: Закриті переходи | H6: ='07A_Конструктор'!I7 -> 0
A7: Зміна пробігу, км/день | B7: =B6-B5 -> 0 | D7: Недоступні потоки | E7: =COUNTIF(G11:G2453,"НЕМАЄ МАРШРУТУ") -> 0 | G7: Перепризначено базових ТТ | H7: =COUNTIF('03B_Призначення_РЦ'!D:D,"Так") -> 100
A8: Зміна пробігу, % | B8: =IFERROR(B7/B5,0) -> 0 | D8: Зачеплені палети/день | E8: =SUMIF(G11:G2453,"ЗМІНЕНО",I11:I2453)+SUMIF(G11:G2453,"НЕМАЄ МАРШРУТУ",I11:I2453) -> 0
A10: Flow_ID | B10: TT_ID | C10: Тип потоку | D10: РЦ | E10: Базовий перехід | F10: Перехід сценарію | G10: Статус | H10: Δ маршруту, км | I10: Палет/день | J10: Рейсів/день | K10: Базовий еквів. пробіг | L10: Сценарний еквів. пробіг | M10: Δ еквів. пробігу | N10: Δ % | O10: Обрана відстань | P10: Тип авто | Q10: Місткість авто | R10: Ліміт РЦ, ТТ | S10: Статус ліміту
A11: ='06A_Варіанти'!A2 -> BASE_1 | B11: ='06A_Варіанти'!B2 -> TT_1 | C11: ='06A_Варіанти'!D2 -> Основний | D11: ='06A_Варіанти'!C2 -> РЦП | E11: ='06A_Варіанти'!S2 -> DIRECT | F11: =IF(O11='06A_Варіанти'!E2,'06A_Варіанти'!E$1,IF(O11='06A_Варіанти'!F2,'06A_Варіанти'!F$1,IF(O11='06A_Варіанти'!G2,'06A_Варіанти'!G$1,IF(O11='06A_Варіанти'!H2,'06A_Варіанти'!H$1,IF(O11='06A_Варіанти'!I2,'06A_Варіанти'!I$1,IF(O11='06A_Варіанти'!J2,'06A_Варіанти'!J$1,IF(O11='06A_Варіанти'!K2,'06A_Варіанти'!K$1,IF(O11='06A_Варіанти'!L2,'06A_Варіанти'!L$1,IF(O11='06A_Варіанти'!M2,'06A_Варіанти'!M$1,IF(O11='06A_Варіанти'!N2,'06A_Варіанти'!N$1,IF(O11='06A_Варіанти'!O2,'06A_Варіанти'!O$1,IF(O11='06A_Варіанти'!P2,'06A_Варіанти'!P$1,IF(O11='06A_Варіанти'!Q2,'06A_Варіанти'!Q$1,IF(O11='06A_Варіанти'!R2,'06A_Варіанти'!R$1,"НЕМАЄ МАРШРУТУ")))))))))))))) -> DIRECT | G11: =IF(O11>1E+90,"НЕМАЄ МАРШРУТУ",IF(F11=E11,"БЕЗ ЗМІН","ЗМІНЕНО")) -> БЕЗ ЗМІН | H11: =IF(G11="НЕМАЄ МАРШРУТУ",0,O11-'06A_Варіанти'!T2) -> 0 | I11: =IFERROR(INDEX('04_Потоки'!$E:$E,MATCH(A11,'04_Потоки'!$A:$A,0)),0) -> 1.8505361 | J11: =ROUNDUP(I11/20,0) -> 1 | K11: =IF(C11="РЦК макси",0,2*'06A_Варіанти'!T2*J11) -> 13.8 | L11: =IF(C11="РЦК макси",0,IF(G11="НЕМАЄ МАРШРУТУ",0,2*O11*J11)) -> 13.8 | M11: =L11-K11 -> 0 | N11: =IFERROR(M11/K11,0) -> 0 | O11: =MIN(IF('07A_Конструктор'!$D$5="Так",'06A_Варіанти'!E2,1E+99),IF('07A_Конструктор'!$D$6="Так",'06A_Варіанти'!F2,1E+99),IF('07A_Конструктор'!$D$7="Так",'06A_Варіанти'!G2,1E+99),IF('07A_Конструктор'!$D$8="Так",'06A_Варіанти'!H2,1E+99),IF('07A_Конструктор'!$D$9="Так",'06A_Варіанти'!I2,1E+99),IF('07A_Конструктор'!$D$10="Так",'06A_Варіанти'!J2,1E+99),IF('07A_Конструктор'!$D$11="Так",'06A_Варіанти'!K2,1E+99),IF('07A_Конструктор'!$D$12="Так",'06A_Варіанти'!L2,1E+99),IF('07A_Конструктор'!$D$13="Так",'06A_Варіанти'!M2,1E+99),IF('07A_Конструктор'!$D$14="Так",'06A_Варіанти'!N2,1E+99),IF('07A_Конструктор'!$D$15="Так",'06A_Варіанти'!O2,1E+99),IF('07A_Конструктор'!$D$16="Так",'06A_Варіанти'!P2,1E+99),IF('07A_Конструктор'!$D$17="Так",'06A_Варіанти'!Q2,1E+99),IF('06A_Варіанти'!R2="",1E+99,'06A_Варіанти'!R2)) -> 6.9 | P11: =IF(C11="РЦК макси","Не моделюється",IF(MOD(I11,20)=0,"10 т",IF(MOD(I11,20)<=14,"5 т",IF(MOD(I11,20)<=16,"7 т","10 т")))) -> 5 т | Q11: =IF(P11="Не моделюється",0,IF(P11="5 т",14,IF(P11="7 т",16,20))) -> 14 | R11: =IF(OR(C11="РЦК макси",C11="РЦЧ SKU"),"SKU-потік",IFERROR(VLOOKUP(D11,'02_РЦ'!$A$3:$I$7,5,FALSE),0)) -> 800 | S11: =IF(OR(C11="РЦК макси",C11="РЦЧ SKU"),"Не рахується в ліміт",IFERROR(VLOOKUP(D11,'02_РЦ'!$A$3:$I$7,9,FALSE),"Немає РЦ")) -> В межах
A12: ='06A_Варіанти'!A3 -> BASE_3 | B12: ='06A_Варіанти'!B3 -> TT_3 | C12: ='06A_Варіанти'!D3 -> Основний | D12: ='06A_Варіанти'!C3 -> РЦП | E12: ='06A_Варіанти'!S3 -> DIRECT | F12: =IF(O12='06A_Варіанти'!E3,'06A_Варіанти'!E$1,IF(O12='06A_Варіанти'!F3,'06A_Варіанти'!F$1,IF(O12='06A_Варіанти'!G3,'06A_Варіанти'!G$1,IF(O12='06A_Варіанти'!H3,'06A_Варіанти'!H$1,IF(O12='06A_Варіанти'!I3,'06A_Варіанти'!I$1,IF(O12='06A_Варіанти'!J3,'06A_Варіанти'!J$1,IF(O12='06A_Варіанти'!K3,'06A_Варіанти'!K$1,IF(O12='06A_Варіанти'!L3,'06A_Варіанти'!L$1,IF(O12='06A_Варіанти'!M3,'06A_Варіанти'!M$1,IF(O12='06A_Варіанти'!N3,'06A_Варіанти'!N$1,IF(O12='06A_Варіанти'!O3,'06A_Варіанти'!O$1,IF(O12='06A_Варіанти'!P3,'06A_Варіанти'!P$1,IF(O12='06A_Варіанти'!Q3,'06A_Варіанти'!Q$1,IF(O12='06A_Варіанти'!R3,'06A_Варіанти'!R$1,"НЕМАЄ МАРШРУТУ")))))))))))))) -> DIRECT | G12: =IF(O12>1E+90,"НЕМАЄ МАРШРУТУ",IF(F12=E12,"БЕЗ ЗМІН","ЗМІНЕНО")) -> БЕЗ ЗМІН | H12: =IF(G12="НЕМАЄ МАРШРУТУ",0,O12-'06A_Варіанти'!T3) -> 0 | I12: =IFERROR(INDEX('04_Потоки'!$E:$E,MATCH(A12,'04_Потоки'!$A:$A,0)),0) -> 1.8505361 | J12: =ROUNDUP(I12/20,0) -> 1 | K12: =IF(C12="РЦК макси",0,2*'06A_Варіанти'!T3*J12) -> 260.2 | L12: =IF(C12="РЦК макси",0,IF(G12="НЕМАЄ МАРШРУТУ",0,2*O12*J12)) -> 260.2 | M12: =L12-K12 -> 0 | N12: =IFERROR(M12/K12,0) -> 0 | O12: =MIN(IF('07A_Конструктор'!$D$5="Так",'06A_Варіанти'!E3,1E+99),IF('07A_Конструктор'!$D$6="Так",'06A_Варіанти'!F3,1E+99),IF('07A_Конструктор'!$D$7="Так",'06A_Варіанти'!G3,1E+99),IF('07A_Конструктор'!$D$8="Так",'06A_Варіанти'!H3,1E+99),IF('07A_Конструктор'!$D$9="Так",'06A_Варіанти'!I3,1E+99),IF('07A_Конструктор'!$D$10="Так",'06A_Варіанти'!J3,1E+99),IF('07A_Конструктор'!$D$11="Так",'06A_Варіанти'!K3,1E+99),IF('07A_Конструктор'!$D$12="Так",'06A_Варіанти'!L3,1E+99),IF('07A_Конструктор'!$D$13="Так",'06A_Варіанти'!M3,1E+99),IF('07A_Конструктор'!$D$14="Так",'06A_Варіанти'!N3,1E+99),IF('07A_Конструктор'!$D$15="Так",'06A_Варіанти'!O3,1E+99),IF('07A_Конструктор'!$D$16="Так",'06A_Варіанти'!P3,1E+99),IF('07A_Конструктор'!$D$17="Так",'06A_Варіанти'!Q3,1E+99),IF('06A_Варіанти'!R3="",1E+99,'06A_Варіанти'!R3)) -> 130.1 | P12: =IF(C12="РЦК макси","Не моделюється",IF(MOD(I12,20)=0,"10 т",IF(MOD(I12,20)<=14,"5 т",IF(MOD(I12,20)<=16,"7 т","10 т")))) -> 5 т | Q12: =IF(P12="Не моделюється",0,IF(P12="5 т",14,IF(P12="7 т",16,20))) -> 14 | R12: =IF(OR(C12="РЦК макси",C12="РЦЧ SKU"),"SKU-потік",IFERROR(VLOOKUP(D12,'02_РЦ'!$A$3:$I$7,5,FALSE),0)) -> 800 | S12: =IF(OR(C12="РЦК макси",C12="РЦЧ SKU"),"Не рахується в ліміт",IFERROR(VLOOKUP(D12,'02_РЦ'!$A$3:$I$7,9,FALSE),"Немає РЦ")) -> В межах
A13: ='06A_Варіанти'!A4 -> BASE_503 | B13: ='06A_Варіанти'!B4 -> TT_503 | C13: ='06A_Варіанти'!D4 -> Основний | D13: ='06A_Варіанти'!C4 -> РЦП | E13: ='06A_Варіанти'!S4 -> DIRECT | F13: =IF(O13='06A_Варіанти'!E4,'06A_Варіанти'!E$1,IF(O13='06A_Варіанти'!F4,'06A_Варіанти'!F$1,IF(O13='06A_Варіанти'!G4,'06A_Варіанти'!G$1,IF(O13='06A_Варіанти'!H4,'06A_Варіанти'!H$1,IF(O13='06A_Варіанти'!I4,'06A_Варіанти'!I$1,IF(O13='06A_Варіанти'!J4,'06A_Варіанти'!J$1,IF(O13='06A_Варіанти'!K4,'06A_Варіанти'!K$1,IF(O13='06A_Варіанти'!L4,'06A_Варіанти'!L$1,IF(O13='06A_Варіанти'!M4,'06A_Варіанти'!M$1,IF(O13='06A_Варіанти'!N4,'06A_Варіанти'!N$1,IF(O13='06A_Варіанти'!O4,'06A_Варіанти'!O$1,IF(O13='06A_Варіанти'!P4,'06A_Варіанти'!P$1,IF(O13='06A_Варіанти'!Q4,'06A_Варіанти'!Q$1,IF(O13='06A_Варіанти'!R4,'06A_Варіанти'!R$1,"НЕМАЄ МАРШРУТУ")))))))))))))) -> DIRECT | G13: =IF(O13>1E+90,"НЕМАЄ МАРШРУТУ",IF(F13=E13,"БЕЗ ЗМІН","ЗМІНЕНО")) -> БЕЗ ЗМІН | H13: =IF(G13="НЕМАЄ МАРШРУТУ",0,O13-'06A_Варіанти'!T4) -> 0 | I13: =IFERROR(INDEX('04_Потоки'!$E:$E,MATCH(A13,'04_Потоки'!$A:$A,0)),0) -> 1.8505361 | J13: =ROUNDUP(I13/20,0) -> 1 | K13: =IF(C13="РЦК макси",0,2*'06A_Варіанти'!T4*J13) -> 301.6 | L13: =IF(C13="РЦК макси",0,IF(G13="НЕМАЄ МАРШРУТУ",0,2*O13*J13)) -> 301.6 | M13: =L13-K13 -> 0 | N13: =IFERROR(M13/K13,0) -> 0 | O13: =MIN(IF('07A_Конструктор'!$D$5="Так",'06A_Варіанти'!E4,1E+99),IF('07A_Конструктор'!$D$6="Так",'06A_Варіанти'!F4,1E+99),IF('07A_Конструктор'!$D$7="Так",'06A_Варіанти'!G4,1E+99),IF('07A_Конструктор'!$D$8="Так",'06A_Варіанти'!H4,1E+99),IF('07A_Конструктор'!$D$9="Так",'06A_Варіанти'!I4,1E+99),IF('07A_Конструктор'!$D$10="Так",'06A_Варіанти'!J4,1E+99),IF('07A_Конструктор'!$D$11="Так",'06A_Варіанти'!K4,1E+99),IF('07A_Конструктор'!$D$12="Так",'06A_Варіанти'!L4,1E+99),IF('07A_Конструктор'!$D$13="Так",'06A_Варіанти'!M4,1E+99),IF('07A_Конструктор'!$D$14="Так",'06A_Варіанти'!N4,1E+99),IF('07A_Конструктор'!$D$15="Так",'06A_Варіанти'!O4,1E+99),IF('07A_Конструктор'!$D$16="Так",'06A_Варіанти'!P4,1E+99),IF('07A_Конструктор'!$D$17="Так",'06A_Варіанти'!Q4,1E+99),IF('06A_Варіанти'!R4="",1E+99,'06A_Варіанти'!R4)) -> 150.8 | P13: =IF(C13="РЦК макси","Не моделюється",IF(MOD(I13,20)=0,"10 т",IF(MOD(I13,20)<=14,"5 т",IF(MOD(I13,20)<=16,"7 т","10 т")))) -> 5 т | Q13: =IF(P13="Не моделюється",0,IF(P13="5 т",14,IF(P13="7 т",16,20))) -> 14 | R13: =IF(OR(C13="РЦК макси",C13="РЦЧ SKU"),"SKU-потік",IFERROR(VLOOKUP(D13,'02_РЦ'!$A$3:$I$7,5,FALSE),0)) -> 800 | S13: =IF(OR(C13="РЦК макси",C13="РЦЧ SKU"),"Не рахується в ліміт",IFERROR(VLOOKUP(D13,'02_РЦ'!$A$3:$I$7,9,FALSE),"Немає РЦ")) -> В межах
A14: ='06A_Варіанти'!A5 -> BASE_515 | B14: ='06A_Варіанти'!B5 -> TT_515 | C14: ='06A_Варіанти'!D5 -> Основний | D14: ='06A_Варіанти'!C5 -> РЦП | E14: ='06A_Варіанти'!S5 -> KAM_HPP | F14: =IF(O14='06A_Варіанти'!E5,'06A_Варіанти'!E$1,IF(O14='06A_Варіанти'!F5,'06A_Варіанти'!F$1,IF(O14='06A_Варіанти'!G5,'06A_Варіанти'!G$1,IF(O14='06A_Варіанти'!H5,'06A_Варіанти'!H$1,IF(O14='06A_Варіанти'!I5,'06A_Варіанти'!I$1,IF(O14='06A_Варіанти'!J5,'06A_Варіанти'!J$1,IF(O14='06A_Варіанти'!K5,'06A_Варіанти'!K$1,IF(O14='06A_Варіанти'!L5,'06A_Варіанти'!L$1,IF(O14='06A_Варіанти'!M5,'06A_Варіанти'!M$1,IF(O14='06A_Варіанти'!N5,'06A_Варіанти'!N$1,IF(O14='06A_Варіанти'!O5,'06A_Варіанти'!O$1,IF(O14='06A_Варіанти'!P5,'06A_Варіанти'!P$1,IF(O14='06A_Варіанти'!Q5,'06A_Варіанти'!Q$1,IF(O14='06A_Варіанти'!R5,'06A_Варіанти'!R$1,"НЕМАЄ МАРШРУТУ")))))))))))))) -> KAM_HPP | G14: =IF(O14>1E+90,"НЕМАЄ МАРШРУТУ",IF(F14=E14,"БЕЗ ЗМІН","ЗМІНЕНО")) -> БЕЗ ЗМІН | H14: =IF(G14="НЕМАЄ МАРШРУТУ",0,O14-'06A_Варіанти'!T5) -> 0 | I14: =IFERROR(INDEX('04_Потоки'!$E:$E,MATCH(A14,'04_Потоки'!$A:$A,0)),0) -> 1.8505361 | J14: =ROUNDUP(I14/20,0) -> 1 | K14: =IF(C14="РЦК макси",0,2*'06A_Варіанти'!T5*J14) -> 465.6 | L14: =IF(C14="РЦК макси",0,IF(G14="НЕМАЄ МАРШРУТУ",0,2*O14*J14)) -> 465.6 | M14: =L14-K14 -> 0 | N14: =IFERROR(M14/K14,0) -> 0 | O14: =MIN(IF('07A_Конструктор'!$D$5="Так",'06A_Варіанти'!E5,1E+99),IF('07A_Конструктор'!$D$6="Так",'06A_Варіанти'!F5,1E+99),IF('07A_Конструктор'!$D$7="Так",'06A_Варіанти'!G5,1E+99),IF('07A_Конструктор'!$D$8="Так",'06A_Варіанти'!H5,1E+99),IF('07A_Конструктор'!$D$9="Так",'06A_Варіанти'!I5,1E+99),IF('07A_Конструктор'!$D$10="Так",'06A_Варіанти'!J5,1E+99),IF('07A_Конструктор'!$D$11="Так",'06A_Варіанти'!K5,1E+99),IF('07A_Конструктор'!$D$12="Так",'06A_Варіанти'!L5,1E+99),IF('07A_Конструктор'!$D$13="Так",'06A_Варіанти'!M5,1E+99),IF('07A_Конструктор'!$D$14="Так",'06A_Варіанти'!N5,1E+99),IF('07A_Конструктор'!$D$15="Так",'06A_Варіанти'!O5,1E+99),IF('07A_Конструктор'!$D$16="Так",'06A_Варіанти'!P5,1E+99),IF('07A_Конструктор'!$D$17="Так",'06A_Варіанти'!Q5,1E+99),IF('06A_Варіанти'!R5="",1E+99,'06A_Варіанти'!R5)) -> 232.8 | P14: =IF(C14="РЦК макси","Не моделюється",IF(MOD(I14,20)=0,"10 т",IF(MOD(I14,20)<=14,"5 т",IF(MOD(I14,20)<=16,"7 т","10 т")))) -> 5 т | Q14: =IF(P14="Не моделюється",0,IF(P14="5 т",14,IF(P14="7 т",16,20))) -> 14 | R14: =IF(OR(C14="РЦК макси",C14="РЦЧ SKU"),"SKU-потік",IFERROR(VLOOKUP(D14,'02_РЦ'!$A$3:$I$7,5,FALSE),0)) -> 800 | S14: =IF(OR(C14="РЦК макси",C14="РЦЧ SKU"),"Не рахується в ліміт",IFERROR(VLOOKUP(D14,'02_РЦ'!$A$3:$I$7,9,FALSE),"Немає РЦ")) -> В межах
A15: ='06A_Варіанти'!A6 -> BASE_178 | B15: ='06A_Варіанти'!B6 -> TT_178 | C15: ='06A_Варіанти'!D6 -> Основний | D15: ='06A_Варіанти'!C6 -> РЦП | E15: ='06A_Варіанти'!S6 -> DNI_AMUR | F15: =IF(O15='06A_Варіанти'!E6,'06A_Варіанти'!E$1,IF(O15='06A_Варіанти'!F6,'06A_Варіанти'!F$1,IF(O15='06A_Варіанти'!G6,'06A_Варіанти'!G$1,IF(O15='06A_Варіанти'!H6,'06A_Варіанти'!H$1,IF(O15='06A_Варіанти'!I6,'06A_Варіанти'!I$1,IF(O15='06A_Варіанти'!J6,'06A_Варіанти'!J$1,IF(O15='06A_Варіанти'!K6,'06A_Варіанти'!K$1,IF(O15='06A_Варіанти'!L6,'06A_Варіанти'!L$1,IF(O15='06A_Варіанти'!M6,'06A_Варіанти'!M$1,IF(O15='06A_Варіанти'!N6,'06A_Варіанти'!N$1,IF(O15='06A_Варіанти'!O6,'06A_Варіанти'!O$1,IF(O15='06A_Варіанти'!P6,'06A_Варіанти'!P$1,IF(O15='06A_Варіанти'!Q6,'06A_Варіанти'!Q$1,IF(O15='06A_Варіанти'!R6,'06A_Варіанти'!R$1,"НЕМАЄ МАРШРУТУ")))))))))))))) -> DNI_AMUR | G15: =IF(O15>1E+90,"НЕМАЄ МАРШРУТУ",IF(F15=E15,"БЕЗ ЗМІН","ЗМІНЕНО")) -> БЕЗ ЗМІН | H15: =IF(G15="НЕМАЄ МАРШРУТУ",0,O15-'06A_Варіанти'!T6) -> 0 | I15: =IFERROR(INDEX('04_Потоки'!$E:$E,MATCH(A15,'04_Потоки'!$A:$A,0)),0) -> 1.8505361 | J15: =ROUNDUP(I15/20,0) -> 1 | K15: =IF(C15="РЦК макси",0,2*'06A_Варіанти'!T6*J15) -> 469 | L15: =IF(C15="РЦК макси",0,IF(G15="НЕМАЄ МАРШРУТУ",0,2*O15*J15)) -> 469 | M15: =L15-K15 -> 0 | N15: =IFERROR(M15/K15,0) -> 0 | O15: =MIN(IF('07A_Конструктор'!$D$5="Так",'06A_Варіанти'!E6,1E+99),IF('07A_Конструктор'!$D$6="Так",'06A_Варіанти'!F6,1E+99),IF('07A_Конструктор'!$D$7="Так",'06A_Варіанти'!G6,1E+99),IF('07A_Конструктор'!$D$8="Так",'06A_Варіанти'!H6,1E+99),IF('07A_Конструктор'!$D$9="Так",'06A_Варіанти'!I6,1E+99),IF('07A_Конструктор'!$D$10="Так",'06A_Варіанти'!J6,1E+99),IF('07A_Конструктор'!$D$11="Так",'06A_Варіанти'!K6,1E+99),IF('07A_Конструктор'!$D$12="Так",'06A_Варіанти'!L6,1E+99),IF('07A_Конструктор'!$D$13="Так",'06A_Варіанти'!M6,1E+99),IF('07A_Конструктор'!$D$14="Так",'06A_Варіанти'!N6,1E+99),IF('07A_Конструктор'!$D$15="Так",'06A_Варіанти'!O6,1E+99),IF('07A_Конструктор'!$D$16="Так",'06A_Варіанти'!P6,1E+99),IF('07A_Конструктор'!$D$17="Так",'06A_Варіанти'!Q6,1E+99),IF('06A_Варіанти'!R6="",1E+99,'06A_Варіанти'!R6)) -> 234.5 | P15: =IF(C15="РЦК макси","Не моделюється",IF(MOD(I15,20)=0,"10 т",IF(MOD(I15,20)<=14,"5 т",IF(MOD(I15,20)<=16,"7 т","10 т")))) -> 5 т | Q15: =IF(P15="Не моделюється",0,IF(P15="5 т",14,IF(P15="7 т",16,20))) -> 14 | R15: =IF(OR(C15="РЦК макси",C15="РЦЧ SKU"),"SKU-потік",IFERROR(VLOOKUP(D15,'02_РЦ'!$A$3:$I$7,5,FALSE),0)) -> 800 | S15: =IF(OR(C15="РЦК макси",C15="РЦЧ SKU"),"Не рахується в ліміт",IFERROR(VLOOKUP(D15,'02_РЦ'!$A$3:$I$7,9,FALSE),"Немає РЦ")) -> В межах
A16: ='06A_Варіанти'!A7 -> BASE_489 | B16: ='06A_Варіанти'!B7 -> TT_489 | C16: ='06A_Варіанти'!D7 -> Основний | D16: ='06A_Варіанти'!C7 -> РЦП | E16: ='06A_Варіанти'!S7 -> DIRECT | F16: =IF(O16='06A_Варіанти'!E7,'06A_Варіанти'!E$1,IF(O16='06A_Варіанти'!F7,'06A_Варіанти'!F$1,IF(O16='06A_Варіанти'!G7,'06A_Варіанти'!G$1,IF(O16='06A_Варіанти'!H7,'06A_Варіанти'!H$1,IF(O16='06A_Варіанти'!I7,'06A_Варіанти'!I$1,IF(O16='06A_Варіанти'!J7,'06A_Варіанти'!J$1,IF(O16='06A_Варіанти'!K7,'06A_Варіанти'!K$1,IF(O16='06A_Варіанти'!L7,'06A_Варіанти'!L$1,IF(O16='06A_Варіанти'!M7,'06A_Варіанти'!M$1,IF(O16='06A_Варіанти'!N7,'06A_Варіанти'!N$1,IF(O16='06A_Варіанти'!O7,'06A_Варіанти'!O$1,IF(O16='06A_Варіанти'!P7,'06A_Варіанти'!P$1,IF(O16='06A_Варіанти'!Q7,'06A_Варіанти'!Q$1,IF(O16='06A_Варіанти'!R7,'06A_Варіанти'!R$1,"НЕМАЄ МАРШРУТУ")))))))))))))) -> DIRECT | G16: =IF(O16>1E+90,"НЕМАЄ МАРШРУТУ",IF(F16=E16,"БЕЗ ЗМІН","ЗМІНЕНО")) -> БЕЗ ЗМІН | H16: =IF(G16="НЕМАЄ МАРШРУТУ",0,O16-'06A_Варіанти'!T7) -> 0 | I16: =IFERROR(INDEX('04_Потоки'!$E:$E,MATCH(A16,'04_Потоки'!$A:$A,0)),0) -> 1.8505361 | J16: =ROUNDUP(I16/20,0) -> 1 | K16: =IF(C16="РЦК макси",0,2*'06A_Варіанти'!T7*J16) -> 369.8 | L16: =IF(C16="РЦК макси",0,IF(G16="НЕМАЄ МАРШРУТУ",0,2*O16*J16)) -> 369.8 | M16: =L16-K16 -> 0 | N16: =IFERROR(M16/K16,0) -> 0 | O16: =MIN(IF('07A_Конструктор'!$D$5="Так",'06A_Варіанти'!E7,1E+99),IF('07A_Конструктор'!$D$6="Так",'06A_Варіанти'!F7,1E+99),IF('07A_Конструктор'!$D$7="Так",'06A_Варіанти'!G7,1E+99),IF('07A_Конструктор'!$D$8="Так",'06A_Варіанти'!H7,1E+99),IF('07A_Конструктор'!$D$9="Так",'06A_Варіанти'!I7,1E+99),IF('07A_Конструктор'!$D$10="Так",'06A_Варіанти'!J7,1E+99),IF('07A_Конструктор'!$D$11="Так",'06A_Варіанти'!K7,1E+99),IF('07A_Конструктор'!$D$12="Так",'06A_Варіанти'!L7,1E+99),IF('07A_Конструктор'!$D$13="Так",'06A_Варіанти'!M7,1E+99),IF('07A_Конструктор'!$D$14="Так",'06A_Варіанти'!N7,1E+99),IF('07A_Конструктор'!$D$15="Так",'06A_Варіанти'!O7,1E+99),IF('07A_Конструктор'!$D$16="Так",'06A_Варіанти'!P7,1E+99),IF('07A_Конструктор'!$D$17="Так",'06A_Варіанти'!Q7,1E+99),IF('06A_Варіанти'!R7="",1E+99,'06A_Варіанти'!R7)) -> 184.9 | P16: =IF(C16="РЦК макси","Не моделюється",IF(MOD(I16,20)=0,"10 т",IF(MOD(I16,20)<=14,"5 т",IF(MOD(I16,20)<=16,"7 т","10 т")))) -> 5 т | Q16: =IF(P16="Не моделюється",0,IF(P16="5 т",14,IF(P16="7 т",16,20))) -> 14 | R16: =IF(OR(C16="РЦК макси",C16="РЦЧ SKU"),"SKU-потік",IFERROR(VLOOKUP(D16,'02_РЦ'!$A$3:$I$7,5,FALSE),0)) -> 800 | S16: =IF(OR(C16="РЦК макси",C16="РЦЧ SKU"),"Не рахується в ліміт",IFERROR(VLOOKUP(D16,'02_РЦ'!$A$3:$I$7,9,FALSE),"Немає РЦ")) -> В межах
A17: ='06A_Варіанти'!A8 -> BASE_185 | B17: ='06A_Варіанти'!B8 -> TT_185 | C17: ='06A_Варіанти'!D8 -> Основний | D17: ='06A_Варіанти'!C8 -> РЦП | E17: ='06A_Варіанти'!S8 -> DIRECT | F17: =IF(O17='06A_Варіанти'!E8,'06A_Варіанти'!E$1,IF(O17='06A_Варіанти'!F8,'06A_Варіанти'!F$1,IF(O17='06A_Варіанти'!G8,'06A_Варіанти'!G$1,IF(O17='06A_Варіанти'!H8,'06A_Варіанти'!H$1,IF(O17='06A_Варіанти'!I8,'06A_Варіанти'!I$1,IF(O17='06A_Варіанти'!J8,'06A_Варіанти'!J$1,IF(O17='06A_Варіанти'!K8,'06A_Варіанти'!K$1,IF(O17='06A_Варіанти'!L8,'06A_Варіанти'!L$1,IF(O17='06A_Варіанти'!M8,'06A_Варіанти'!M$1,IF(O17='06A_Варіанти'!N8,'06A_Варіанти'!N$1,IF(O17='06A_Варіанти'!O8,'06A_Варіанти'!O$1,IF(O17='06A_Варіанти'!P8,'06A_Варіанти'!P$1,IF(O17='06A_Варіанти'!Q8,'06A_Варіанти'!Q$1,IF(O17='06A_Варіанти'!R8,'06A_Варіанти'!R$1,"НЕМАЄ МАРШРУТУ")))))))))))))) -> DIRECT | G17: =IF(O17>1E+90,"НЕМАЄ МАРШРУТУ",IF(F17=E17,"БЕЗ ЗМІН","ЗМІНЕНО")) -> БЕЗ ЗМІН | H17: =IF(G17="НЕМАЄ МАРШРУТУ",0,O17-'06A_Варіанти'!T8) -> 0 | I17: =IFERROR(INDEX('04_Потоки'!$E:$E,MATCH(A17,'04_Потоки'!$A:$A,0)),0) -> 1.8505361 | J17: =ROUNDUP(I17/20,0) -> 1 | K17: =IF(C17="РЦК макси",0,2*'06A_Варіанти'!T8*J17) -> 452.6 | L17: =IF(C17="РЦК макси",0,IF(G17="НЕМАЄ МАРШРУТУ",0,2*O17*J17)) -> 452.6 | M17: =L17-K17 -> 0 | N17: =IFERROR(M17/K17,0) -> 0 | O17: =MIN(IF('07A_Конструктор'!$D$5="Так",'06A_Варіанти'!E8,1E+99),IF('07A_Конструктор'!$D$6="Так",'06A_Варіанти'!F8,1E+99),IF('07A_Конструктор'!$D$7="Так",'06A_Варіанти'!G8,1E+99),IF('07A_Конструктор'!$D$8="Так",'06A_Варіанти'!H8,1E+99),IF('07A_Конструктор'!$D$9="Так",'06A_Варіанти'!I8,1E+99),IF('07A_Конструктор'!$D$10="Так",'06A_Варіанти'!J8,1E+99),IF('07A_Конструктор'!$D$11="Так",'06A_Варіанти'!K8,1E+99),IF('07A_Конструктор'!$D$12="Так",'06A_Варіанти'!L8,1E+99),IF('07A_Конструктор'!$D$13="Так",'06A_Варіанти'!M8,1E+99),IF('07A_Конструктор'!$D$14="Так",'06A_Варіанти'!N8,1E+99),IF('07A_Конструктор'!$D$15="Так",'06A_Варіанти'!O8,1E+99),IF('07A_Конструктор'!$D$16="Так",'06A_Варіанти'!P8,1E+99),IF('07A_Конструктор'!$D$17="Так",'06A_Варіанти'!Q8,1E+99),IF('06A_Варіанти'!R8="",1E+99,'06A_Варіанти'!R8)) -> 226.3 | P17: =IF(C17="РЦК макси","Не моделюється",IF(MOD(I17,20)=0,"10 т",IF(MOD(I17,20)<=14,"5 т",IF(MOD(I17,20)<=16,"7 т","10 т")))) -> 5 т | Q17: =IF(P17="Не моделюється",0,IF(P17="5 т",14,IF(P17="7 т",16,20))) -> 14 | R17: =IF(OR(C17="РЦК макси",C17="РЦЧ SKU"),"SKU-потік",IFERROR(VLOOKUP(D17,'02_РЦ'!$A$3:$I$7,5,FALSE),0)) -> 800 | S17: =IF(OR(C17="РЦК макси",C17="РЦЧ SKU"),"Не рахується в ліміт",IFERROR(VLOOKUP(D17,'02_РЦ'!$A$3:$I$7,9,FALSE),"Немає РЦ")) -> В межах
A18: ='06A_Варіанти'!A9 -> BASE_518 | B18: ='06A_Варіанти'!B9 -> TT_518 | C18: ='06A_Варіанти'!D9 -> Основний | D18: ='06A_Варіанти'!C9 -> РЦП | E18: ='06A_Варіанти'!S9 -> DIRECT | F18: =IF(O18='06A_Варіанти'!E9,'06A_Варіанти'!E$1,IF(O18='06A_Варіанти'!F9,'06A_Варіанти'!F$1,IF(O18='06A_Варіанти'!G9,'06A_Варіанти'!G$1,IF(O18='06A_Варіанти'!H9,'06A_Варіанти'!H$1,IF(O18='06A_Варіанти'!I9,'06A_Варіанти'!I$1,IF(O18='06A_Варіанти'!J9,'06A_Варіанти'!J$1,IF(O18='06A_Варіанти'!K9,'06A_Варіанти'!K$1,IF(O18='06A_Варіанти'!L9,'06A_Варіанти'!L$1,IF(O18='06A_Варіанти'!M9,'06A_Варіанти'!M$1,IF(O18='06A_Варіанти'!N9,'06A_Варіанти'!N$1,IF(O18='06A_Варіанти'!O9,'06A_Варіанти'!O$1,IF(O18='06A_Варіанти'!P9,'06A_Варіанти'!P$1,IF(O18='06A_Варіанти'!Q9,'06A_Варіанти'!Q$1,IF(O18='06A_Варіанти'!R9,'06A_Варіанти'!R$1,"НЕМАЄ МАРШРУТУ")))))))))))))) -> DIRECT | G18: =IF(O18>1E+90,"НЕМАЄ МАРШРУТУ",IF(F18=E18,"БЕЗ ЗМІН","ЗМІНЕНО")) -> БЕЗ ЗМІН | H18: =IF(G18="НЕМАЄ МАРШРУТУ",0,O18-'06A_Варіанти'!T9) -> 0 | I18: =IFERROR(INDEX('04_Потоки'!$E:$E,MATCH(A18,'04_Потоки'!$A:$A,0)),0) -> 1.8505361 | J18: =ROUNDUP(I18/20,0) -> 1 | K18: =IF(C18="РЦК макси",0,2*'06A_Варіанти'!T9*J18) -> 337.8 | L18: =IF(C18="РЦК макси",0,IF(G18="НЕМАЄ МАРШРУТУ",0,2*O18*J18)) -> 337.8 | M18: =L18-K18 -> 0 | N18: =IFERROR(M18/K18,0) -> 0 | O18: =MIN(IF('07A_Конструктор'!$D$5="Так",'06A_Варіанти'!E9,1E+99),IF('07A_Конструктор'!$D$6="Так",'06A_Варіанти'!F9,1E+99),IF('07A_Конструктор'!$D$7="Так",'06A_Варіанти'!G9,1E+99),IF('07A_Конструктор'!$D$8="Так",'06A_Варіанти'!H9,1E+99),IF('07A_Конструктор'!$D$9="Так",'06A_Варіанти'!I9,1E+99),IF('07A_Конструктор'!$D$10="Так",'06A_Варіанти'!J9,1E+99),IF('07A_Конструктор'!$D$11="Так",'06A_Варіанти'!K9,1E+99),IF('07A_Конструктор'!$D$12="Так",'06A_Варіанти'!L9,1E+99),IF('07A_Конструктор'!$D$13="Так",'06A_Варіанти'!M9,1E+99),IF('07A_Конструктор'!$D$14="Так",'06A_Варіанти'!N9,1E+99),IF('07A_Конструктор'!$D$15="Так",'06A_Варіанти'!O9,1E+99),IF('07A_Конструктор'!$D$16="Так",'06A_Варіанти'!P9,1E+99),IF('07A_Конструктор'!$D$17="Так",'06A_Варіанти'!Q9,1E+99),IF('06A_Варіанти'!R9="",1E+99,'06A_Варіанти'!R9)) -> 168.9 | P18: =IF(C18="РЦК макси","Не моделюється",IF(MOD(I18,20)=0,"10 т",IF(MOD(I18,20)<=14,"5 т",IF(MOD(I18,20)<=16,"7 т","10 т")))) -> 5 т | Q18: =IF(P18="Не моделюється",0,IF(P18="5 т",14,IF(P18="7 т",16,20))) -> 14 | R18: =IF(OR(C18="РЦК макси",C18="РЦЧ SKU"),"SKU-потік",IFERROR(VLOOKUP(D18,'02_РЦ'!$A$3:$I$7,5,FALSE),0)) -> 800 | S18: =IF(OR(C18="РЦК макси",C18="РЦЧ SKU"),"Не рахується в ліміт",IFERROR(VLOOKUP(D18,'02_РЦ'!$A$3:$I$7,9,FALSE),"Немає РЦ")) -> В межах
A19: ='06A_Варіанти'!A10 -> BASE_519 | B19: ='06A_Варіанти'!B10 -> TT_519 | C19: ='06A_Варіанти'!D10 -> Основний | D19: ='06A_Варіанти'!C10 -> РЦП | E19: ='06A_Варіанти'!S10 -> DIRECT | F19: =IF(O19='06A_Варіанти'!E10,'06A_Варіанти'!E$1,IF(O19='06A_Варіанти'!F10,'06A_Варіанти'!F$1,IF(O19='06A_Варіанти'!G10,'06A_Варіанти'!G$1,IF(O19='06A_Варіанти'!H10,'06A_Варіанти'!H$1,IF(O19='06A_Варіанти'!I10,'06A_Варіанти'!I$1,IF(O19='06A_Варіанти'!J10,'06A_Варіанти'!J$1,IF(O19='06A_Варіанти'!K10,'06A_Варіанти'!K$1,IF(O19='06A_Варіанти'!L10,'06A_Варіанти'!L$1,IF(O19='06A_Варіанти'!M10,'06A_Варіанти'!M$1,IF(O19='06A_Варіанти'!N10,'06A_Варіанти'!N$1,IF(O19='06A_Варіанти'!O10,'06A_Варіанти'!O$1,IF(O19='06A_Варіанти'!P10,'06A_Варіанти'!P$1,IF(O19='06A_Варіанти'!Q10,'06A_Варіанти'!Q$1,IF(O19='06A_Варіанти'!R10,'06A_Варіанти'!R$1,"НЕМАЄ МАРШРУТУ")))))))))))))) -> DIRECT | G19: =IF(O19>1E+90,"НЕМАЄ МАРШРУТУ",IF(F19=E19,"БЕЗ ЗМІН","ЗМІНЕНО")) -> БЕЗ ЗМІН | H19: =IF(G19="НЕМАЄ МАРШРУТУ",0,O19-'06A_Варіанти'!T10) -> 0 | I19: =IFERROR(INDEX('04_Потоки'!$E:$E,MATCH(A19,'04_Потоки'!$A:$A,0)),0) -> 1.8505361 | J19: =ROUNDUP(I19/20,0) -> 1 | K19: =IF(C19="РЦК макси",0,2*'06A_Варіанти'!T10*J19) -> 325.4 | L19: =IF(C19="РЦК макси",0,IF(G19="НЕМАЄ МАРШРУТУ",0,2*O19*J19)) -> 325.4 | M19: =L19-K19 -> 0 | N19: =IFERROR(M19/K19,0) -> 0 | O19: =MIN(IF('07A_Конструктор'!$D$5="Так",'06A_Варіанти'!E10,1E+99),IF('07A_Конструктор'!$D$6="Так",'06A_Варіанти'!F10,1E+99),IF('07A_Конструктор'!$D$7="Так",'06A_Варіанти'!G10,1E+99),IF('07A_Конструктор'!$D$8="Так",'06A_Варіанти'!H10,1E+99),IF('07A_Конструктор'!$D$9="Так",'06A_Варіанти'!I10,1E+99),IF('07A_Конструктор'!$D$10="Так",'06A_Варіанти'!J10,1E+99),IF('07A_Конструктор'!$D$11="Так",'06A_Варіанти'!K10,1E+99),IF('07A_Конструктор'!$D$12="Так",'06A_Варіанти'!L10,1E+99),IF('07A_Конструктор'!$D$13="Так",'06A_Варіанти'!M10,1E+99),IF('07A_Конструктор'!$D$14="Так",'06A_Варіанти'!N10,1E+99),IF('07A_Конструктор'!$D$15="Так",'06A_Варіанти'!O10,1E+99),IF('07A_Конструктор'!$D$16="Так",'06A_Варіанти'!P10,1E+99),IF('07A_Конструктор'!$D$17="Так",'06A_Варіанти'!Q10,1E+99),IF('06A_Варіанти'!R10="",1E+99,'06A_Варіанти'!R10)) -> 162.7 | P19: =IF(C19="РЦК макси","Не моделюється",IF(MOD(I19,20)=0,"10 т",IF(MOD(I19,20)<=14,"5 т",IF(MOD(I19,20)<=16,"7 т","10 т")))) -> 5 т | Q19: =IF(P19="Не моделюється",0,IF(P19="5 т",14,IF(P19="7 т",16,20))) -> 14 | R19: =IF(OR(C19="РЦК макси",C19="РЦЧ SKU"),"SKU-потік",IFERROR(VLOOKUP(D19,'02_РЦ'!$A$3:$I$7,5,FALSE),0)) -> 800 | S19: =IF(OR(C19="РЦК макси",C19="РЦЧ SKU"),"Не рахується в ліміт",IFERROR(VLOOKUP(D19,'02_РЦ'!$A$3:$I$7,9,FALSE),"Немає РЦ")) -> В межах
A20: ='06A_Варіанти'!A11 -> BASE_5 | B20: ='06A_Варіанти'!B11 -> TT_5 | C20: ='06A_Варіанти'!D11 -> Основний | D20: ='06A_Варіанти'!C11 -> РЦП | E20: ='06A_Варіанти'!S11 -> DIRECT | F20: =IF(O20='06A_Варіанти'!E11,'06A_Варіанти'!E$1,IF(O20='06A_Варіанти'!F11,'06A_Варіанти'!F$1,IF(O20='06A_Варіанти'!G11,'06A_Варіанти'!G$1,IF(O20='06A_Варіанти'!H11,'06A_Варіанти'!H$1,IF(O20='06A_Варіанти'!I11,'06A_Варіанти'!I$1,IF(O20='06A_Варіанти'!J11,'06A_Варіанти'!J$1,IF(O20='06A_Варіанти'!K11,'06A_Варіанти'!K$1,IF(O20='06A_Варіанти'!L11,'06A_Варіанти'!L$1,IF(O20='06A_Варіанти'!M11,'06A_Варіанти'!M$1,IF(O20='06A_Варіанти'!N11,'06A_Варіанти'!N$1,IF(O20='06A_Варіанти'!O11,'06A_Варіанти'!O$1,IF(O20='06A_Варіанти'!P11,'06A_Варіанти'!P$1,IF(O20='06A_Варіанти'!Q11,'06A_Варіанти'!Q$1,IF(O20='06A_Варіанти'!R11,'06A_Варіанти'!R$1,"НЕМАЄ МАРШРУТУ")))))))))))))) -> DIRECT | G20: =IF(O20>1E+90,"НЕМАЄ МАРШРУТУ",IF(F20=E20,"БЕЗ ЗМІН","ЗМІНЕНО")) -> БЕЗ ЗМІН | H20: =IF(G20="НЕМАЄ МАРШРУТУ",0,O20-'06A_Варіанти'!T11) -> 0 | I20: =IFERROR(INDEX('04_Потоки'!$E:$E,MATCH(A20,'04_Потоки'!$A:$A,0)),0) -> 1.8505361 | J20: =ROUNDUP(I20/20,0) -> 1 | K20: =IF(C20="РЦК макси",0,2*'06A_Варіанти'!T11*J20) -> 370.2 | L20: =IF(C20="РЦК макси",0,IF(G20="НЕМАЄ МАРШРУТУ",0,2*O20*J20)) -> 370.2 | M20: =L20-K20 -> 0 | N20: =IFERROR(M20/K20,0) -> 0 | O20: =MIN(IF('07A_Конструктор'!$D$5="Так",'06A_Варіанти'!E11,1E+99),IF('07A_Конструктор'!$D$6="Так",'06A_Варіанти'!F11,1E+99),IF('07A_Конструктор'!$D$7="Так",'06A_Варіанти'!G11,1E+99),IF('07A_Конструктор'!$D$8="Так",'06A_Варіанти'!H11,1E+99),IF('07A_Конструктор'!$D$9="Так",'06A_Варіанти'!I11,1E+99),IF('07A_Конструктор'!$D$10="Так",'06A_Варіанти'!J11,1E+99),IF('07A_Конструктор'!$D$11="Так",'06A_Варіанти'!K11,1E+99),IF('07A_Конструктор'!$D$12="Так",'06A_Варіанти'!L11,1E+99),IF('07A_Конструктор'!$D$13="Так",'06A_Варіанти'!M11,1E+99),IF('07A_Конструктор'!$D$14="Так",'06A_Варіанти'!N11,1E+99),IF('07A_Конструктор'!$D$15="Так",'06A_Варіанти'!O11,1E+99),IF('07A_Конструктор'!$D$16="Так",'06A_Варіанти'!P11,1E+99),IF('07A_Конструктор'!$D$17="Так",'06A_Варіанти'!Q11,1E+99),IF('06A_Варіанти'!R11="",1E+99,'06A_Варіанти'!R11)) -> 185.1 | P20: =IF(C20="РЦК макси","Не моделюється",IF(MOD(I20,20)=0,"10 т",IF(MOD(I20,20)<=14,"5 т",IF(MOD(I20,20)<=16,"7 т","10 т")))) -> 5 т | Q20: =IF(P20="Не моделюється",0,IF(P20="5 т",14,IF(P20="7 т",16,20))) -> 14 | R20: =IF(OR(C20="РЦК макси",C20="РЦЧ SKU"),"SKU-потік",IFERROR(VLOOKUP(D20,'02_РЦ'!$A$3:$I$7,5,FALSE),0)) -> 800 | S20: =IF(OR(C20="РЦК макси",C20="РЦЧ SKU"),"Не рахується в ліміт",IFERROR(VLOOKUP(D20,'02_РЦ'!$A$3:$I$7,9,FALSE),"Немає РЦ")) -> В межах
A21: ='06A_Варіанти'!A12 -> BASE_7 | B21: ='06A_Варіанти'!B12 -> TT_7 | C21: ='06A_Варіанти'!D12 -> Основний | D21: ='06A_Варіанти'!C12 -> РЦП | E21: ='06A_Варіанти'!S12 -> KREM | F21: =IF(O21='06A_Варіанти'!E12,'06A_Варіанти'!E$1,IF(O21='06A_Варіанти'!F12,'06A_Варіанти'!F$1,IF(O21='06A_Варіанти'!G12,'06A_Варіанти'!G$1,IF(O21='06A_Варіанти'!H12,'06A_Варіанти'!H$1,IF(O21='06A_Варіанти'!I12,'06A_Варіанти'!I$1,IF(O21='06A_Варіанти'!J12,'06A_Варіанти'!J$1,IF(O21='06A_Варіанти'!K12,'06A_Варіанти'!K$1,IF(O21='06A_Варіанти'!L12,'06A_Варіанти'!L$1,IF(O21='06A_Варіанти'!M12,'06A_Варіанти'!M$1,IF(O21='06A_Варіанти'!N12,'06A_Варіанти'!N$1,IF(O21='06A_Варіанти'!O12,'06A_Варіанти'!O$1,IF(O21='06A_Варіанти'!P12,'06A_Варіанти'!P$1,IF(O21='06A_Варіанти'!Q12,'06A_Варіанти'!Q$1,IF(O21='06A_Варіанти'!R12,'06A_Варіанти'!R$1,"НЕМАЄ МАРШРУТУ")))))))))))))) -> KREM | G21: =IF(O21>1E+90,"НЕМАЄ МАРШРУТУ",IF(F21=E21,"БЕЗ ЗМІН","ЗМІНЕНО")) -> БЕЗ ЗМІН | H21: =IF(G21="НЕМАЄ МАРШРУТУ",0,O21-'06A_Варіанти'!T12) -> 0 | I21: =IFERROR(INDEX('04_Потоки'!$E:$E,MATCH(A21,'04_Потоки'!$A:$A,0)),0) -> 1.8505361 | J21: =ROUNDUP(I21/20,0) -> 1 | K21: =IF(C21="РЦК макси",0,2*'06A_Варіанти'!T12*J21) -> 232 | L21: =IF(C21="РЦК макси",0,IF(G21="НЕМАЄ МАРШРУТУ",0,2*O21*J21)) -> 232 | M21: =L21-K21 -> 0 | N21: =IFERROR(M21/K21,0) -> 0 | O21: =MIN(IF('07A_Конструктор'!$D$5="Так",'06A_Варіанти'!E12,1E+99),IF('07A_Конструктор'!$D$6="Так",'06A_Варіанти'!F12,1E+99),IF('07A_Конструктор'!$D$7="Так",'06A_Варіанти'!G12,1E+99),IF('07A_Конструктор'!$D$8="Так",'06A_Варіанти'!H12,1E+99),IF('07A_Конструктор'!$D$9="Так",'06A_Варіанти'!I12,1E+99),IF('07A_Конструктор'!$D$10="Так",'06A_Варіанти'!J12,1E+99),IF('07A_Конструктор'!$D$11="Так",'06A_Варіанти'!K12,1E+99),IF('07A_Конструктор'!$D$12="Так",'06A_Варіанти'!L12,1E+99),IF('07A_Конструктор'!$D$13="Так",'06A_Варіанти'!M12,1E+99),IF('07A_Конструктор'!$D$14="Так",'06A_Варіанти'!N12,1E+99),IF('07A_Конструктор'!$D$15="Так",'06A_Варіанти'!O12,1E+99),IF('07A_Конструктор'!$D$16="Так",'06A_Варіанти'!P12,1E+99),IF('07A_Конструктор'!$D$17="Так",'06A_Варіанти'!Q12,1E+99),IF('06A_Варіанти'!R12="",1E+99,'06A_Варіанти'!R12)) -> 116 | P21: =IF(C21="РЦК макси","Не моделюється",IF(MOD(I21,20)=0,"10 т",IF(MOD(I21,20)<=14,"5 т",IF(MOD(I21,20)<=16,"7 т","10 т")))) -> 5 т | Q21: =IF(P21="Не моделюється",0,IF(P21="5 т",14,IF(P21="7 т",16,20))) -> 14 | R21: =IF(OR(C21="РЦК макси",C21="РЦЧ SKU"),"SKU-потік",IFERROR(VLOOKUP(D21,'02_РЦ'!$A$3:$I$7,5,FALSE),0)) -> 800 | S21: =IF(OR(C21="РЦК макси",C21="РЦЧ SKU"),"Не рахується в ліміт",IFERROR(VLOOKUP(D21,'02_РЦ'!$A$3:$I$7,9,FALSE),"Немає РЦ")) -> В межах
A22: ='06A_Варіанти'!A13 -> BASE_9 | B22: ='06A_Варіанти'!B13 -> TT_9 | C22: ='06A_Варіанти'!D13 -> Основний | D22: ='06A_Варіанти'!C13 -> РЦП | E22: ='06A_Варіанти'!S13 -> DIRECT | F22: =IF(O22='06A_Варіанти'!E13,'06A_Варіанти'!E$1,IF(O22='06A_Варіанти'!F13,'06A_Варіанти'!F$1,IF(O22='06A_Варіанти'!G13,'06A_Варіанти'!G$1,IF(O22='06A_Варіанти'!H13,'06A_Варіанти'!H$1,IF(O22='06A_Варіанти'!I13,'06A_Варіанти'!I$1,IF(O22='06A_Варіанти'!J13,'06A_Варіанти'!J$1,IF(O22='06A_Варіанти'!K13,'06A_Варіанти'!K$1,IF(O22='06A_Варіанти'!L13,'06A_Варіанти'!L$1,IF(O22='06A_Варіанти'!M13,'06A_Варіанти'!M$1,IF(O22='06A_Варіанти'!N13,'06A_Варіанти'!N$1,IF(O22='06A_Варіанти'!O13,'06A_Варіанти'!O$1,IF(O22='06A_Варіанти'!P13,'06A_Варіанти'!P$1,IF(O22='06A_Варіанти'!Q13,'06A_Варіанти'!Q$1,IF(O22='06A_Варіанти'!R13,'06A_Варіанти'!R$1,"НЕМАЄ МАРШРУТУ")))))))))))))) -> DIRECT | G22: =IF(O22>1E+90,"НЕМАЄ МАРШРУТУ",IF(F22=E22,"БЕЗ ЗМІН","ЗМІНЕНО")) -> БЕЗ ЗМІН | H22: =IF(G22="НЕМАЄ МАРШРУТУ",0,O22-'06A_Варіанти'!T13) -> 0 | I22: =IFERROR(INDEX('04_Потоки'!$E:$E,MATCH(A22,'04_Потоки'!$A:$A,0)),0) -> 1.8505361 | J22: =ROUNDUP(I22/20,0) -> 1 | K22: =IF(C22="РЦК макси",0,2*'06A_Варіанти'!T13*J22) -> 11.6 | L22: =IF(C22="РЦК макси",0,IF(G22="НЕМАЄ МАРШРУТУ",0,2*O22*J22)) -> 11.6 | M22: =L22-K22 -> 0 | N22: =IFERROR(M22/K22,0) -> 0 | O22: =MIN(IF('07A_Конструктор'!$D$5="Так",'06A_Варіанти'!E13,1E+99),IF('07A_Конструктор'!$D$6="Так",'06A_Варіанти'!F13,1E+99),IF('07A_Конструктор'!$D$7="Так",'06A_Варіанти'!G13,1E+99),IF('07A_Конструктор'!$D$8="Так",'06A_Варіанти'!H13,1E+99),IF('07A_Конструктор'!$D$9="Так",'06A_Варіанти'!I13,1E+99),IF('07A_Конструктор'!$D$10="Так",'06A_Варіанти'!J13,1E+99),IF('07A_Конструктор'!$D$11="Так",'06A_Варіанти'!K13,1E+99),IF('07A_Конструктор'!$D$12="Так",'06A_Варіанти'!L13,1E+99),IF('07A_Конструктор'!$D$13="Так",'06A_Варіанти'!M13,1E+99),IF('07A_Конструктор'!$D$14="Так",'06A_Варіанти'!N13,1E+99),IF('07A_Конструктор'!$D$15="Так",'06A_Варіанти'!O13,1E+99),IF('07A_Конструктор'!$D$16="Так",'06A_Варіанти'!P13,1E+99),IF('07A_Конструктор'!$D$17="Так",'06A_Варіанти'!Q13,1E+99),IF('06A_Варіанти'!R13="",1E+99,'06A_Варіанти'!R13)) -> 5.8 | P22: =IF(C22="РЦК макси","Не моделюється",IF(MOD(I22,20)=0,"10 т",IF(MOD(I22,20)<=14,"5 т",IF(MOD(I22,20)<=16,"7 т","10 т")))) -> 5 т | Q22: =IF(P22="Не моделюється",0,IF(P22="5 т",14,IF(P22="7 т",16,20))) -> 14 | R22: =IF(OR(C22="РЦК макси",C22="РЦЧ SKU"),"SKU-потік",IFERROR(VLOOKUP(D22,'02_РЦ'!$A$3:$I$7,5,FALSE),0)) -> 800 | S22: =IF(OR(C22="РЦК макси",C22="РЦЧ SKU"),"Не рахується в ліміт",IFERROR(VLOOKUP(D22,'02_РЦ'!$A$3:$I$7,9,FALSE),"Немає РЦ")) -> В межах
... A2453: ='06A_Варіанти'!A2444 -> RCCH_3452 | B2453: ='06A_Варіанти'!B2444 -> TT_3452 | C2453: ='06A_Варіанти'!D2444 -> РЦЧ SKU | D2453: ='06A_Варіанти'!C2444 -> РЦЧ | E2453: ='06A_Варіанти'!S2444 -> DIRECT | F2453: =IF(O2453='06A_Варіанти'!E2444,'06A_Варіанти'!E$1,IF(O2453='06A_Варіанти'!F2444,'06A_Варіанти'!F$1,IF(O2453='06A_Варіанти'!G2444,'06A_Варіанти'!G$1,IF(O2453='06A_Варіанти'!H2444,'06A_Варіанти'!H$1,IF(O2453='06A_Варіанти'!I2444,'06A_Варіанти'!I$1,IF(O2453='06A_Варіанти'!J2444,'06A_Варіанти'!J$1,IF(O2453='06A_Варіанти'!K2444,'06A_Варіанти'!K$1,IF(O2453='06A_Варіанти'!L2444,'06A_Варіанти'!L$1,IF(O2453='06A_Варіанти'!M2444,'06A_Варіанти'!M$1,IF(O2453='06A_Варіанти'!N2444,'06A_Варіанти'!N$1,IF(O2453='06A_Варіанти'!O2444,'06A_Варіанти'!O$1,IF(O2453='06A_Варіанти'!P2444,'06A_Варіанти'!P$1,IF(O2453='06A_Варіанти'!Q2444,'06A_Варіанти'!Q$1,IF(O2453='06A_Варіанти'!R2444,'06A_Варіанти'!R$1,"НЕМАЄ МАРШРУТУ")))))))))))))) -> DIRECT | G2453: =IF(O2453>1E+90,"НЕМАЄ МАРШРУТУ",IF(F2453=E2453,"БЕЗ ЗМІН","ЗМІНЕНО")) -> БЕЗ ЗМІН | H2453: =IF(G2453="НЕМАЄ МАРШРУТУ",0,O2453-'06A_Варіанти'!T2444) -> 0 | I2453: =IFERROR(INDEX('04_Потоки'!$E:$E,MATCH(A2453,'04_Потоки'!$A:$A,0)),0) -> 1 | J2453: =ROUNDUP(I2453/20,0) -> 1 | K2453: =IF(C2453="РЦК макси",0,2*'06A_Варіанти'!T2444*J2453) -> 589 | L2453: =IF(C2453="РЦК макси",0,IF(G2453="НЕМАЄ МАРШРУТУ",0,2*O2453*J2453)) -> 589 | M2453: =L2453-K2453 -> 0 | N2453: =IFERROR(M2453/K2453,0) -> 0 | O2453: =MIN(IF('07A_Конструктор'!$D$5="Так",'06A_Варіанти'!E2444,1E+99),IF('07A_Конструктор'!$D$6="Так",'06A_Варіанти'!F2444,1E+99),IF('07A_Конструктор'!$D$7="Так",'06A_Варіанти'!G2444,1E+99),IF('07A_Конструктор'!$D$8="Так",'06A_Варіанти'!H2444,1E+99),IF('07A_Конструктор'!$D$9="Так",'06A_Варіанти'!I2444,1E+99),IF('07A_Конструктор'!$D$10="Так",'06A_Варіанти'!J2444,1E+99),IF('07A_Конструктор'!$D$11="Так",'06A_Варіанти'!K2444,1E+99),IF('07A_Конструктор'!$D$12="Так",'06A_Варіанти'!L2444,1E+99),IF('07A_Конструктор'!$D$13="Так",'06A_Варіанти'!M2444,1E+99),IF('07A_Конструктор'!$D$14="Так",'06A_Варіанти'!N2444,1E+99),IF('07A_Конструктор'!$D$15="Так",'06A_Варіанти'!O2444,1E+99),IF('07A_Конструктор'!$D$16="Так",'06A_Варіанти'!P2444,1E+99),IF('07A_Конструктор'!$D$17="Так",'06A_Варіанти'!Q2444,1E+99),IF('06A_Варіанти'!R2444="",1E+99,'06A_Варіанти'!R2444)) -> 294.5 | P2453: =IF(C2453="РЦК макси","Не моделюється",IF(MOD(I2453,20)=0,"10 т",IF(MOD(I2453,20)<=14,"5 т",IF(MOD(I2453,20)<=16,"7 т","10 т")))) -> 5 т | Q2453: =IF(P2453="Не моделюється",0,IF(P2453="5 т",14,IF(P2453="7 т",16,20))) -> 14 | R2453: =IF(OR(C2453="РЦК макси",C2453="РЦЧ SKU"),"SKU-потік",IFERROR(VLOOKUP(D2453,'02_РЦ'!$A$3:$I$7,5,FALSE),0)) -> SKU-потік | S2453: =IF(OR(C2453="РЦК макси",C2453="РЦЧ SKU"),"Не рахується в ліміт",IFERROR(VLOOKUP(D2453,'02_РЦ'!$A$3:$I$7,9,FALSE),"Немає РЦ")) -> Не рахується в ліміт

Sheet 02_РЦ
A1: ДОВІДНИК РОЗПОДІЛЬЧИХ ЦЕНТРІВ
A2: Код РЦ | B2: Назва РЦ | C2: Широта | D2: Довгота | E2: Ліміт, ТТ | F2: Доступний | G2: Тип | H2: Базові унікальні ТТ | I2: Статус ліміту | J2: Примітка
A3: РЦП | B3: Щербані | C3: 49.533378 | D3: 34.538489 | E3: 800 | F3: Так | G3: Основний | H3: 800 | I3: В межах | J3: Паралельні потоки РЦК/РЦЧ не дублюють ТТ у ліміті
A4: РЦВ | B4: Вінниця, Житомирський в’їзд | C4: 49.28275 | D4: 28.49681 | E4: 500 | F4: Так | G4: Основний | H4: 500 | I4: В межах | J4: Паралельні потоки РЦК/РЦЧ не дублюють ТТ у ліміті
A5: РЦЛ | B5: Львів, вул. Північна | C5: 49.83366 | D5: 23.92729 | E5: 700 | F5: Так | G5: Основний | H5: 614 | I5: В межах | J5: Паралельні потоки РЦК/РЦЧ не дублюють ТТ у ліміті
A6: РЦК | B6: Стоянка | C6: 50.45833 | D6: 30.23 | E6: 200 | F6: Так | G6: Основний | H6: 15 | I6: В межах | J6: Паралельні потоки РЦК/РЦЧ не дублюють ТТ у ліміті
A7: РЦЧ | B7: Черкаси | C7: 49.4444 | D7: 32.0598 | E7: 200 | F7: Так | G7: Паралельний SKU-потік | H7: 0 | I7: В межах | J7: Паралельні потоки РЦК/РЦЧ не дублюють ТТ у ліміті

Sheet 03_ТТ
A1: ПОВНИЙ ДОВІДНИК ТОРГОВИХ ТОЧОК
A2: TT_ID | B2: Статус | C2: Номер ТТ | D2: Місто | E2: Чинний РЦ | F2: Широта | G2: Довгота | H2: Палети джерела | I2: Є потік РЦЧ | J2: Контроль дубля | K2: Контроль координат | L2: Початковий РЦ
A3: TT_1 | B3: Діючий | C3: 1 | D3: м. Полтава | E3: РЦП | F3: 49.585117 | G3: 34.544373 | H3: 55.516084 | I3: Ні | J3: =IF(COUNTIF($A$3:A3,A3)>1,"ДУБЛЬ","") | K3: =IF(OR(F3="",G3=""),"НЕМАЄ","OK") -> OK | L3: РЦП
A4: TT_3 | B4: Діючий | C4: 3 | D4: м. Тростянець | E4: РЦП | F4: 50.47018 | G4: 34.96003 | H4: 55.516084 | I4: Ні | J4: =IF(COUNTIF($A$3:A4,A4)>1,"ДУБЛЬ","") | K4: =IF(OR(F4="",G4=""),"НЕМАЄ","OK") -> OK | L4: РЦП
A5: TT_503 | B5: Діючий | C5: 503 | D5: смт Липова Долина | E5: РЦП | F5: 50.558687 | G5: 33.799326 | H5: 55.516084 | I5: Ні | J5: =IF(COUNTIF($A$3:A5,A5)>1,"ДУБЛЬ","") | K5: =IF(OR(F5="",G5=""),"НЕМАЄ","OK") -> OK | L5: РЦП
A6: TT_515 | B6: Діючий | C6: 515 | D6: смт Томаківка | E6: РЦП | F6: 47.81054 | G6: 34.74199 | H6: 55.516084 | I6: Ні | J6: =IF(COUNTIF($A$3:A6,A6)>1,"ДУБЛЬ","") | K6: =IF(OR(F6="",G6=""),"НЕМАЄ","OK") -> OK | L6: РЦП
A7: TT_178 | B7: Діючий | C7: 178 | D7: м. Запоріжжя | E7: РЦП | F7: 47.823201 | G7: 35.039616 | H7: 55.516084 | I7: Ні | J7: =IF(COUNTIF($A$3:A7,A7)>1,"ДУБЛЬ","") | K7: =IF(OR(F7="",G7=""),"НЕМАЄ","OK") -> OK | L7: РЦП
A8: TT_489 | B8: Діючий | C8: 489 | D8: м. Павлоград | E8: РЦП | F8: 48.4986 | G8: 35.944651 | H8: 55.516084 | I8: Ні | J8: =IF(COUNTIF($A$3:A8,A8)>1,"ДУБЛЬ","") | K8: =IF(OR(F8="",G8=""),"НЕМАЄ","OK") -> OK | L8: РЦП
A9: TT_185 | B9: Діючий | C9: 185 | D9: м. Вільнянськ | E9: РЦП | F9: 47.944225 | G9: 35.435904 | H9: 55.516084 | I9: Ні | J9: =IF(COUNTIF($A$3:A9,A9)>1,"ДУБЛЬ","") | K9: =IF(OR(F9="",G9=""),"НЕМАЄ","OK") -> OK | L9: РЦП
A10: TT_518 | B10: Діючий | C10: 518 | D10: м. Харків | E10: РЦП | F10: 50.011913 | G10: 36.352861 | H10: 55.516084 | I10: Ні | J10: =IF(COUNTIF($A$3:A10,A10)>1,"ДУБЛЬ","") | K10: =IF(OR(F10="",G10=""),"НЕМАЄ","OK") -> OK | L10: РЦП
A11: TT_519 | B11: Діючий | C11: 519 | D11: м. Харків | E11: РЦП | F11: 49.944916 | G11: 36.315095 | H11: 55.516084 | I11: Ні | J11: =IF(COUNTIF($A$3:A11,A11)>1,"ДУБЛЬ","") | K11: =IF(OR(F11="",G11=""),"НЕМАЄ","OK") -> OK | L11: РЦП
A12: TT_5 | B12: Діючий | C12: 5 | D12: м. Ромни | E12: РЦП | F12: 50.746597 | G12: 33.489347 | H12: 55.516084 | I12: Ні | J12: =IF(COUNTIF($A$3:A12,A12)>1,"ДУБЛЬ","") | K12: =IF(OR(F12="",G12=""),"НЕМАЄ","OK") -> OK | L12: РЦП
A13: TT_7 | B13: Діючий | C13: 7 | D13: м. Кременчук | E13: РЦП | F13: 49.064631 | G13: 33.418272 | H13: 55.516084 | I13: Так | J13: =IF(COUNTIF($A$3:A13,A13)>1,"ДУБЛЬ","") | K13: =IF(OR(F13="",G13=""),"НЕМАЄ","OK") -> OK | L13: РЦП
A14: TT_9 | B14: Діючий | C14: 9 | D14: м. Полтава | E14: РЦП | F14: 49.569286 | G14: 34.576676 | H14: 55.516084 | I14: Ні | J14: =IF(COUNTIF($A$3:A14,A14)>1,"ДУБЛЬ","") | K14: =IF(OR(F14="",G14=""),"НЕМАЄ","OK") -> OK | L14: РЦП
... A1931: TT_3486 | B1931: Діючий | C1931: 3486 | D1931: с. Ярунь | E1931: РЦЛ | F1931: 50.54654 | G1931: 27.46682 | H1931: 59.726384 | I1931: Ні | J1931: =IF(COUNTIF($A$3:A1931,A1931)>1,"ДУБЛЬ","") | K1931: =IF(OR(F1931="",G1931=""),"НЕМАЄ","OK") -> OK | L1931: РЦЛ

Sheet 03B_Призначення_РЦ
A1: TT_ID | B1: Початковий РЦ | C1: Розрахунковий РЦ | D1: Змінено | E1: Причина
A2: TT_1 | B2: РЦП | C2: РЦП | D2: Ні | E2: В межах ліміту
A3: TT_3 | B3: РЦП | C3: РЦП | D3: Ні | E3: В межах ліміту
A4: TT_503 | B4: РЦП | C4: РЦП | D4: Ні | E4: В межах ліміту
A5: TT_515 | B5: РЦП | C5: РЦП | D5: Ні | E5: В межах ліміту
A6: TT_178 | B6: РЦП | C6: РЦП | D6: Ні | E6: В межах ліміту
A7: TT_489 | B7: РЦП | C7: РЦП | D7: Ні | E7: В межах ліміту
A8: TT_185 | B8: РЦП | C8: РЦП | D8: Ні | E8: В межах ліміту
A9: TT_518 | B9: РЦП | C9: РЦП | D9: Ні | E9: В межах ліміту
A10: TT_519 | B10: РЦП | C10: РЦП | D10: Ні | E10: В межах ліміту
A11: TT_5 | B11: РЦП | C11: РЦП | D11: Ні | E11: В межах ліміту
A12: TT_7 | B12: РЦП | C12: РЦП | D12: Ні | E12: В межах ліміту
... A1930: TT_3486 | B1930: РЦЛ | C1930: РЦЛ | D1930: Ні | E1930: В межах ліміту

Sheet 04_Потоки
A1: РЕЄСТР ТОВАРНИХ ПОТОКІВ
A2: Flow_ID | B2: TT_ID | C2: Тип потоку | D2: РЦ відправлення | E2: Палет/день | F2: Активний | G2: Основний маршрут | H2: Резерв 1 | I2: Резерв 2
A3: BASE_1 | B3: TT_1 | C3: Основний | D3: РЦП | E3: 1.8505361 | F3: Так | G3: Не розраховано
A4: BASE_3 | B4: TT_3 | C4: Основний | D4: РЦП | E4: 1.8505361 | F4: Так | G4: Не розраховано
A5: BASE_503 | B5: TT_503 | C5: Основний | D5: РЦП | E5: 1.8505361 | F5: Так | G5: Не розраховано
A6: BASE_515 | B6: TT_515 | C6: Основний | D6: РЦП | E6: 1.8505361 | F6: Так | G6: Не розраховано
A7: BASE_178 | B7: TT_178 | C7: Основний | D7: РЦП | E7: 1.8505361 | F7: Так | G7: Не розраховано
A8: BASE_489 | B8: TT_489 | C8: Основний | D8: РЦП | E8: 1.8505361 | F8: Так | G8: Не розраховано
A9: BASE_185 | B9: TT_185 | C9: Основний | D9: РЦП | E9: 1.8505361 | F9: Так | G9: Не розраховано
A10: BASE_518 | B10: TT_518 | C10: Основний | D10: РЦП | E10: 1.8505361 | F10: Так | G10: Не розраховано
A11: BASE_519 | B11: TT_519 | C11: Основний | D11: РЦП | E11: 1.8505361 | F11: Так | G11: Не розраховано
A12: BASE_5 | B12: TT_5 | C12: Основний | D12: РЦП | E12: 1.8505361 | F12: Так | G12: Не розраховано
A13: BASE_7 | B13: TT_7 | C13: Основний | D13: РЦП | E13: 1.8505361 | F13: Так | G13: Не розраховано
A14: BASE_9 | B14: TT_9 | C14: Основний | D14: РЦП | E14: 1.8505361 | F14: Так | G14: Не розраховано
... A2445: RCCH_3452 | B2445: TT_3452 | C2445: РЦЧ SKU | D2445: РЦЧ | E2445: 1 | F2445: Так | G2445: Не розраховано

Sheet 05_Переходи
A1: ПОГОДЖЕНІ 13 РОБОЧИХ ПЕРЕХОДІВ
A2: Bridge_ID | B2: Вузол | C2: Назва переходу | D2: Широта | E2: Довгота | F2: Дозволений | G2: Потужність | H2: Статус
A3: KYI_DARN | B3: Київ | C3: Дарницький міст | D3: 50.4306 | E3: 30.5883 | F3: Так | H3: Працює
A4: KYI_SOUTH | B4: Київ | C4: Південний міст | D4: 50.3942 | E4: 30.59 | F4: Так | H4: Працює
A5: KYI_NORTH | B5: Київ | C5: Північний міст | D5: 50.4872 | E5: 30.5408 | F5: Так | H5: Працює
A6: KYI_HPP | B6: Вишгород | C6: Київська ГЕС | D6: 50.5909 | E6: 30.5215 | F6: Так | H6: Працює
A7: KANIV_HPP | B7: Канів | C7: Канівська ГЕС | D7: 49.766 | E7: 31.469 | F7: Так | H7: Працює
A8: CHK | B8: Черкаси | C8: Черкаський міст | D8: 49.448 | E8: 32.093 | F8: Так | H8: Працює
A9: KREM | B9: Кременчук | C9: Кременчуцький міст | D9: 49.069 | E9: 33.42 | F9: Так | H9: Працює
A10: KAM_HPP | B10: Кам’янське | C10: Середньодніпровська ГЕС | D10: 48.551 | E10: 34.474 | F10: Так | H10: Працює
A11: DNI_AMUR | B11: Дніпро | C11: Амурський міст | D11: 48.486 | E11: 35.023 | F11: Так | H11: Працює
A12: DNI_CENTR | B12: Дніпро | C12: Центральний міст | D12: 48.468 | E12: 35.067 | F12: Так | H12: Працює
A13: DNI_SOUTH | B13: Дніпро | C13: Південний міст | D13: 48.414 | E13: 35.103 | F13: Так | H13: Працює
A14: ZP_PREOBR | B14: Запоріжжя | C14: Мости Преображенського | D14: 47.841 | E14: 35.078 | F14: Так | H14: Працює
A15: ZP_NEW | B15: Запоріжжя | C15: Нові мостові переходи | D15: 47.833 | E15: 35.118 | F15: Так | H15: Працює

Sheet 06_Матриця_маршрутів
A1: МАТРИЦЯ ДОПУСТИМИХ МАРШРУТІВ
A2: Route_ID | B2: Flow_ID | C2: РЦ | D2: TT_ID | E2: Bridge_ID | F2: Тип маршруту | G2: РЦ–міст, км | H2: Міст–ТТ, км | I2: Пряма РЦ–ТТ, км | J2: Усього, км | K2: Міст доступний | L2: Маршрут доступний | M2: Ранг
J3: =IF(F3="Без мосту",I3,G3+H3) -> 0 | L3: =IF(E3="DIRECT",TRUE,K3) -> 0

Sheet 06A_Варіанти
A1: Flow_ID | B1: TT_ID | C1: РЦ | D1: Тип потоку | E1: KYI_DARN | F1: KYI_SOUTH | G1: KYI_NORTH | H1: KYI_HPP | I1: KANIV_HPP | J1: CHK | K1: KREM | L1: KAM_HPP | M1: DNI_AMUR | N1: DNI_CENTR | O1: DNI_SOUTH | P1: ZP_PREOBR | Q1: ZP_NEW | R1: DIRECT | S1: Базовий маршрут | T1: Базова відстань, км
A2: BASE_1 | B2: TT_1 | C2: РЦП | D2: Основний | E2: 716.9 | F2: 713.7 | G2: 729.2 | H2: 741.4 | I2: 533.6 | J2: 425.4 | K2: 235 | L2: 269.3 | M2: 298.6 | N2: 305.4 | O2: 321.1 | P2: 468.2 | Q2: 471.7 | R2: 6.9 | S2: DIRECT | T2: 6.9
A3: BASE_3 | B3: TT_3 | C3: РЦП | D3: Основний | E3: 730.8 | F3: 729.3 | G3: 740.8 | H3: 748.6 | I3: 580.1 | J3: 493.6 | K3: 344.6 | L3: 390.7 | M3: 410.9 | N3: 416.8 | O3: 432 | P3: 581.7 | Q3: 584.7 | R3: 130.1 | S3: DIRECT | T3: 130.1
A4: BASE_503 | B4: TT_503 | C4: РЦП | D4: Основний | E4: 632.5 | F4: 631.2 | G4: 642.2 | H4: 649.6 | I4: 492.5 | J4: 420.5 | K4: 316.8 | L4: 405.4 | M4: 442.2 | N4: 449.3 | O4: 465 | P4: 610.1 | Q4: 614 | R4: 150.8 | S4: DIRECT | T4: 150.8
A5: BASE_515 | B5: TT_515 | C5: РЦП | D5: Основний | E5: 863 | F5: 858.1 | G5: 877.3 | H5: 894.2 | I5: 655.3 | J5: 532.1 | K5: 320 | L5: 232.8 | M5: 239.6 | N5: 241.9 | O5: 244 | P5: 261.1 | Q5: 266.4 | S5: KAM_HPP | T5: 232.8
A6: BASE_178 | B6: TT_178 | C6: РЦП | D6: Основний | E6: 880.9 | F6: 876 | G6: 895.1 | H6: 911.6 | I6: 674 | J6: 550.6 | K6: 334.9 | L6: 240.6 | M6: 234.5 | N6: 235.6 | O6: 236.4 | P6: 234.9 | Q6: 239.7 | S6: DNI_AMUR | T6: 234.5
A7: BASE_489 | B7: TT_489 | C7: РЦП | D7: Основний | E7: 890.5 | F7: 886.6 | G7: 903.7 | H7: 917.9 | I7: 692.7 | J7: 572.6 | K7: 350 | L7: 261.4 | M7: 227.6 | N7: 227.2 | O7: 232.7 | P7: 347.6 | Q7: 347.9 | R7: 184.9 | S7: DIRECT | T7: 184.9
A8: BASE_185 | B8: TT_185 | C8: РЦП | D8: Основний | E8: 896.6 | F8: 892 | G8: 910.6 | H8: 926.4 | I8: 691.6 | J8: 568.5 | K8: 348.3 | L8: 248.9 | M8: 227.1 | N8: 226.7 | O8: 226.7 | P8: 265.6 | Q8: 264.6 | R8: 226.3 | S8: DIRECT | T8: 226.3
A9: BASE_518 | B9: TT_518 | C9: РЦП | D9: Основний | E9: 854.6 | F9: 852.5 | G9: 865.4 | H9: 874.7 | I9: 688 | J9: 587.2 | K9: 398.7 | L9: 385.6 | M9: 380.3 | N9: 384 | O9: 396.8 | P9: 541.2 | Q9: 542.8 | R9: 168.9 | S9: DIRECT | T9: 168.9
A10: BASE_519 | B10: TT_519 | C10: РЦП | D10: Основний | E10: 852.8 | F10: 850.6 | G10: 863.8 | H10: 873.3 | I10: 684.5 | J10: 582.6 | K10: 392.1 | L10: 376.8 | M10: 370.9 | N10: 374.6 | O10: 387.3 | P10: 531.7 | Q10: 533.3 | R10: 162.7 | S10: DIRECT | T10: 162.7
A11: BASE_5 | B11: TT_5 | C11: РЦП | D11: Основний | E11: 608.7 | F11: 608 | G11: 617.6 | H11: 623.7 | I11: 483.4 | J11: 422.8 | K11: 339.3 | L11: 436.3 | M11: 475.5 | N11: 482.7 | O11: 498.4 | P11: 642.4 | Q11: 646.3 | R11: 185.1 | S11: DIRECT | T11: 185.1
A12: BASE_7 | B12: TT_7 | C12: РЦП | D12: Основний | E12: 663.9 | F12: 659.4 | G12: 677.8 | H12: 693.7 | I12: 460.3 | J12: 338.5 | K12: 116 | L12: 246.5 | M12: 306.9 | N12: 314.9 | O12: 329.1 | P12: 450.4 | Q12: 455.3 | S12: KREM | T12: 116
A13: BASE_9 | B13: TT_9 | C13: РЦП | D13: Основний | E13: 720.2 | F13: 717.1 | G13: 732.5 | H13: 744.8 | I13: 536.6 | J13: 428.1 | K13: 236.1 | L13: 267.4 | M13: 295.8 | N13: 302.6 | O13: 318.2 | P13: 465.6 | Q13: 469.1 | R13: 5.8 | S13: DIRECT | T13: 5.8
A14: BASE_11 | B14: TT_11 | C14: РЦП | D14: Основний | E14: 720.9 | F14: 720.1 | G14: 729.6 | H14: 735.1 | I14: 588.8 | J14: 514.6 | K14: 388 | L14: 447.4 | M14: 470.2 | N14: 476.3 | O14: 491.6 | P14: 641.2 | Q14: 644.3 | R14: 185.2 | S14: DIRECT | T14: 185.2
A15: BASE_12 | B15: TT_12 | C15: РЦП | D15: Основний | E15: 662.5 | F15: 658 | G15: 676.4 | H15: 692.2 | I15: 459.4 | J15: 337.9 | K15: 118.4 | L15: 247.9 | M15: 307.8 | N15: 315.8 | O15: 330.1 | P15: 452.4 | Q15: 457.3 | R15: 113.1 | S15: DIRECT | T15: 113.1
A16: BASE_24 | B16: TT_24 | C16: РЦП | D16: Основний | E16: 624.6 | F16: 621.8 | G16: 636.4 | H16: 647.8 | I16: 452.8 | J16: 360.2 | K16: 236.3 | L16: 334.7 | M16: 379 | N16: 386.6 | O16: 402.2 | P16: 542.4 | Q16: 546.6 | R16: 99 | S16: DIRECT | T16: 99
A17: BASE_39 | B17: TT_39 | C17: РЦП | D17: Основний | E17: 649.7 | F17: 644.3 | G17: 664.3 | H17: 682.5 | I17: 441 | J17: 321.4 | K17: 196.5 | L17: 292.5 | M17: 356.6 | N17: 364.3 | O17: 376.7 | P17: 475.2 | Q17: 480.7 | S17: KREM | T17: 196.5
A18: BASE_60 | B18: TT_60 | C18: РЦП | D18: Основний | E18: 828 | F18: 823.6 | G18: 841.7 | H18: 857.2 | I18: 625 | J18: 502.6 | K18: 280.2 | L18: 181.7 | M18: 156.6 | N18: 159.3 | O18: 166.2 | P18: 306.7 | Q18: 309.9 | S18: DNI_AMUR | T18: 156.6
A19: BASE_61 | B19: TT_61 | C19: РЦП | D19: Основний | E19: 719.6 | F19: 716.5 | G19: 731.9 | H19: 744.1 | I19: 536.3 | J19: 428 | K19: 236.7 | L19: 268.7 | M19: 297.1 | N19: 303.9 | O19: 319.5 | P19: 466.9 | Q19: 470.4 | R19: 6.9 | S19: DIRECT | T19: 6.9
A20: BASE_62 | B20: TT_62 | C20: РЦП | D20: Основний | E20: 890.2 | F20: 886.3 | G20: 903.5 | H20: 917.7 | I20: 692.3 | J20: 572.2 | K20: 349.6 | L20: 260.7 | M20: 226.8 | N20: 226.5 | O20: 231.8 | P20: 346.5 | Q20: 346.8 | R20: 185 | S20: DIRECT | T20: 185
A21: BASE_46 | B21: TT_46 | C21: РЦП | D21: Основний | E21: 721 | F21: 717.9 | G21: 733.3 | H21: 745.5 | I21: 537.9 | J21: 429.6 | K21: 238.3 | L21: 269.3 | M21: 297.1 | N21: 303.9 | O21: 319.5 | P21: 467.1 | Q21: 470.6 | R21: 8.2 | S21: DIRECT | T21: 8.2
A22: BASE_66 | B22: TT_66 | C22: РЦП | D22: Основний | E22: 516.2 | F22: 519 | G22: 517.2 | H22: 511.9 | I22: 499.7 | J22: 494.7 | K22: 486.3 | L22: 608.8 | M22: 658.6 | N22: 666.3 | O22: 681.8 | P22: 817.2 | Q22: 821.8 | R22: 378.7 | S22: DIRECT | T22: 378.7
A23: BASE_67 | B23: TT_67 | C23: РЦП | D23: Основний | E23: 720.4 | F23: 719.7 | G23: 729.1 | H23: 734.6 | I23: 588.4 | J23: 514.3 | K23: 387.9 | L23: 447.4 | M23: 470.3 | N23: 476.4 | O23: 491.7 | P23: 641.3 | Q23: 644.3 | R23: 185.2 | S23: DIRECT | T23: 185.2
A24: BASE_68 | B24: TT_68 | C24: РЦП | D24: Основний | E24: 720.2 | F24: 717 | G24: 732.5 | H24: 744.7 | I24: 536.8 | J24: 428.4 | K24: 236.9 | L24: 268.3 | M24: 296.6 | N24: 303.4 | O24: 319.1 | P24: 466.4 | Q24: 470 | R24: 6.8 | S24: DIRECT | T24: 6.8
A25: BASE_72 | B25: TT_72 | C25: РЦП | D25: Основний | E25: 780.8 | F25: 776.4 | G25: 794.5 | H25: 810 | I25: 577.8 | J25: 455.6 | K25: 233 | L25: 141.8 | M25: 190 | N25: 197.9 | O25: 211.8 | P25: 342.8 | Q25: 347 | R25: 123.7 | S25: DIRECT | T25: 123.7
A26: BASE_73 | B26: TT_73 | C26: РЦП | D26: Основний | E26: 604.9 | F26: 601.6 | G26: 617.5 | H26: 630.5 | I26: 422.5 | J26: 323.8 | K26: 211.6 | L26: 326.2 | M26: 376.9 | N26: 384.7 | O26: 400.1 | P26: 534.6 | Q26: 539.1 | R26: 114.2 | S26: DIRECT | T26: 114.2
A27: BASE_76 | B27: TT_76 | C27: РЦП | D27: Основний | E27: 824.8 | F27: 820.5 | G27: 838.5 | H27: 853.9 | I27: 622.2 | J27: 500 | K27: 277.4 | L27: 179.9 | M27: 151.6 | N27: 155.9 | O27: 167.3 | P27: 311.9 | Q27: 315.1 | S27: DNI_AMUR | T27: 151.6
A28: BASE_30 | B28: TT_30 | C28: РЦП | D28: Основний | E28: 648.3 | F28: 646.5 | G28: 658.6 | H28: 667.2 | I28: 497.1 | J28: 416.3 | K28: 296.1 | L28: 378.1 | M28: 413.6 | N28: 420.6 | O28: 436.3 | P28: 582 | Q28: 585.8 | R28: 121.8 | S28: DIRECT | T28: 121.8
A29: BASE_77 | B29: TT_77 | C29: РЦП | D29: Основний | E29: 661.8 | F29: 657.3 | G29: 675.7 | H29: 691.5 | I29: 458.7 | J29: 337.3 | K29: 118.8 | L29: 248.6 | M29: 308.5 | N29: 316.5 | O29: 330.8 | P29: 453.1 | Q29: 458 | R29: 113.3 | S29: DIRECT | T29: 113.3
A30: BASE_80 | B30: TT_80 | C30: РЦП | D30: Основний | E30: 517.8 | F30: 520.6 | G30: 518.7 | H30: 513.3 | I30: 501.6 | J30: 496.6 | K30: 488.1 | L30: 610.6 | M30: 660.3 | N30: 668 | O30: 683.5 | P30: 818.9 | Q30: 823.5 | R30: 380.2 | S30: DIRECT | T30: 380.2
A31: BASE_79 | B31: TT_79 | C31: РЦП | D31: Основний | E31: 723.4 | F31: 722.7 | G31: 732.1 | H31: 737.7 | I31: 591.2 | J31: 516.8 | K31: 389.4 | L31: 447.9 | M31: 470.4 | N31: 476.4 | O31: 491.7 | P31: 641.3 | Q31: 644.4 | R31: 185.7 | S31: DIRECT | T31: 185.7
A32: BASE_78 | B32: TT_78 | C32: РЦП | D32: Основний | E32: 781.8 | F32: 777.4 | G32: 795.6 | H32: 811.1 | I32: 578.7 | J32: 456.4 | K32: 233.9 | L32: 140.9 | M32: 189.3 | N32: 197.3 | O32: 211 | P32: 341.3 | Q32: 345.6 | R32: 125.3 | S32: DIRECT | T32: 125.3
